<?xml version="1.0" encoding="UTF-8"?>
<testng-results skipped="0" failed="31" ignored="0" total="48" passed="17">
  <reporter-output>
  </reporter-output>
  <suite name="Suite" duration-ms="80910" started-at="2021-03-14T15:51:07 GMT" finished-at="2021-03-14T15:52:27 GMT">
    <groups>
    </groups>
    <test name="Division" duration-ms="48655" started-at="2021-03-14T15:51:07 GMT" finished-at="2021-03-14T15:51:55 GMT">
      <class name="Acacemy.DivisionTests">
        <test-method status="PASS" signature="initialization()[pri:0, instance:Acacemy.DivisionTests@4b553d26]" name="initialization" is-config="true" duration-ms="7192" started-at="2021-03-14T15:51:07 GMT" finished-at="2021-03-14T15:51:14 GMT">
          <reporter-output>
          </reporter-output>
        </test-method> <!-- initialization -->
        <test-method status="FAIL" signature="DivideAscendRangeAndDescendRange()[pri:0, instance:Acacemy.DivisionTests@4b553d26]" name="DivideAscendRangeAndDescendRange" duration-ms="7447" started-at="2021-03-14T15:51:14 GMT" finished-at="2021-03-14T15:51:21 GMT">
          <exception class="java.lang.AssertionError">
            <message>
              <![CDATA[expected [0.1818382677861246] but found [0.01848358272588151]]]>
            </message>
            <full-stacktrace>
              <![CDATA[java.lang.AssertionError: expected [0.1818382677861246] but found [0.01848358272588151]
at org.testng.Assert.fail(Assert.java:99)
at org.testng.Assert.failNotEquals(Assert.java:1037)
at org.testng.Assert.assertEqualsImpl(Assert.java:140)
at org.testng.Assert.assertEquals(Assert.java:122)
at org.testng.Assert.assertEquals(Assert.java:629)
at org.testng.Assert.assertEquals(Assert.java:639)
at Acacemy.DivisionTests.DivideAscendRangeAndDescendRange(DivisionTests.java:29)
at sun.reflect.NativeMethodAccessorImpl.invoke0(Native Method)
at sun.reflect.NativeMethodAccessorImpl.invoke(NativeMethodAccessorImpl.java:62)
at sun.reflect.DelegatingMethodAccessorImpl.invoke(DelegatingMethodAccessorImpl.java:43)
at java.lang.reflect.Method.invoke(Method.java:498)
at org.testng.internal.MethodInvocationHelper.invokeMethod(MethodInvocationHelper.java:132)
at org.testng.internal.TestInvoker.invokeMethod(TestInvoker.java:599)
at org.testng.internal.TestInvoker.invokeTestMethod(TestInvoker.java:174)
at org.testng.internal.MethodRunner.runInSequence(MethodRunner.java:46)
at org.testng.internal.TestInvoker$MethodInvocationAgent.invoke(TestInvoker.java:822)
at org.testng.internal.TestInvoker.invokeTestMethods(TestInvoker.java:147)
at org.testng.internal.TestMethodWorker.invokeTestMethods(TestMethodWorker.java:146)
at org.testng.internal.TestMethodWorker.run(TestMethodWorker.java:128)
at java.util.ArrayList.forEach(ArrayList.java:1257)
at org.testng.TestRunner.privateRun(TestRunner.java:764)
at org.testng.TestRunner.run(TestRunner.java:585)
at org.testng.SuiteRunner.runTest(SuiteRunner.java:384)
at org.testng.SuiteRunner.access$000(SuiteRunner.java:28)
at org.testng.SuiteRunner$SuiteWorker.run(SuiteRunner.java:425)
at org.testng.internal.thread.ThreadUtil.lambda$execute$0(ThreadUtil.java:66)
at java.util.concurrent.FutureTask.run(FutureTask.java:266)
at java.util.concurrent.ThreadPoolExecutor.runWorker(ThreadPoolExecutor.java:1149)
at java.util.concurrent.ThreadPoolExecutor$Worker.run(ThreadPoolExecutor.java:624)
at java.lang.Thread.run(Thread.java:748)
]]>
            </full-stacktrace>
          </exception> <!-- java.lang.AssertionError -->
          <reporter-output>
          </reporter-output>
        </test-method> <!-- DivideAscendRangeAndDescendRange -->
        <test-method status="FAIL" signature="DivideDecimalTwoPointTwoMinusOne()[pri:0, instance:Acacemy.DivisionTests@4b553d26]" name="DivideDecimalTwoPointTwoMinusOne" duration-ms="5611" started-at="2021-03-14T15:51:22 GMT" description="Divideition test of zero and minus one" finished-at="2021-03-14T15:51:27 GMT">
          <exception class="java.lang.AssertionError">
            <message>
              <![CDATA[expected [0.45] but found [0.4500000001]]]>
            </message>
            <full-stacktrace>
              <![CDATA[java.lang.AssertionError: expected [0.45] but found [0.4500000001]
at org.testng.Assert.fail(Assert.java:99)
at org.testng.Assert.failNotEquals(Assert.java:1037)
at org.testng.Assert.assertEqualsImpl(Assert.java:140)
at org.testng.Assert.assertEquals(Assert.java:122)
at org.testng.Assert.assertEquals(Assert.java:629)
at org.testng.Assert.assertEquals(Assert.java:639)
at Acacemy.DivisionTests.DivideDecimalTwoPointTwoMinusOne(DivisionTests.java:76)
at sun.reflect.NativeMethodAccessorImpl.invoke0(Native Method)
at sun.reflect.NativeMethodAccessorImpl.invoke(NativeMethodAccessorImpl.java:62)
at sun.reflect.DelegatingMethodAccessorImpl.invoke(DelegatingMethodAccessorImpl.java:43)
at java.lang.reflect.Method.invoke(Method.java:498)
at org.testng.internal.MethodInvocationHelper.invokeMethod(MethodInvocationHelper.java:132)
at org.testng.internal.TestInvoker.invokeMethod(TestInvoker.java:599)
at org.testng.internal.TestInvoker.invokeTestMethod(TestInvoker.java:174)
at org.testng.internal.MethodRunner.runInSequence(MethodRunner.java:46)
at org.testng.internal.TestInvoker$MethodInvocationAgent.invoke(TestInvoker.java:822)
at org.testng.internal.TestInvoker.invokeTestMethods(TestInvoker.java:147)
at org.testng.internal.TestMethodWorker.invokeTestMethods(TestMethodWorker.java:146)
at org.testng.internal.TestMethodWorker.run(TestMethodWorker.java:128)
at java.util.ArrayList.forEach(ArrayList.java:1257)
at org.testng.TestRunner.privateRun(TestRunner.java:764)
at org.testng.TestRunner.run(TestRunner.java:585)
at org.testng.SuiteRunner.runTest(SuiteRunner.java:384)
at org.testng.SuiteRunner.access$000(SuiteRunner.java:28)
at org.testng.SuiteRunner$SuiteWorker.run(SuiteRunner.java:425)
at org.testng.internal.thread.ThreadUtil.lambda$execute$0(ThreadUtil.java:66)
at java.util.concurrent.FutureTask.run(FutureTask.java:266)
at java.util.concurrent.ThreadPoolExecutor.runWorker(ThreadPoolExecutor.java:1149)
at java.util.concurrent.ThreadPoolExecutor$Worker.run(ThreadPoolExecutor.java:624)
at java.lang.Thread.run(Thread.java:748)
]]>
            </full-stacktrace>
          </exception> <!-- java.lang.AssertionError -->
          <reporter-output>
          </reporter-output>
        </test-method> <!-- DivideDecimalTwoPointTwoMinusOne -->
        <test-method status="PASS" signature="DivideMorethanTwoNumbers()[pri:0, instance:Acacemy.DivisionTests@4b553d26]" name="DivideMorethanTwoNumbers" duration-ms="5612" started-at="2021-03-14T15:51:28 GMT" finished-at="2021-03-14T15:51:33 GMT">
          <reporter-output>
          </reporter-output>
        </test-method> <!-- DivideMorethanTwoNumbers -->
        <test-method status="FAIL" signature="DivideNegativeandPostiveNumbers()[pri:0, instance:Acacemy.DivisionTests@4b553d26]" name="DivideNegativeandPostiveNumbers" duration-ms="5359" started-at="2021-03-14T15:51:33 GMT" description="Divideition test of zero and minus one" finished-at="2021-03-14T15:51:39 GMT">
          <exception class="java.lang.AssertionError">
            <message>
              <![CDATA[expected [-1.4] but found [1.4000000001]]]>
            </message>
            <full-stacktrace>
              <![CDATA[java.lang.AssertionError: expected [-1.4] but found [1.4000000001]
at org.testng.Assert.fail(Assert.java:99)
at org.testng.Assert.failNotEquals(Assert.java:1037)
at org.testng.Assert.assertEqualsImpl(Assert.java:140)
at org.testng.Assert.assertEquals(Assert.java:122)
at org.testng.Assert.assertEquals(Assert.java:629)
at org.testng.Assert.assertEquals(Assert.java:639)
at Acacemy.DivisionTests.DivideNegativeandPostiveNumbers(DivisionTests.java:70)
at sun.reflect.NativeMethodAccessorImpl.invoke0(Native Method)
at sun.reflect.NativeMethodAccessorImpl.invoke(NativeMethodAccessorImpl.java:62)
at sun.reflect.DelegatingMethodAccessorImpl.invoke(DelegatingMethodAccessorImpl.java:43)
at java.lang.reflect.Method.invoke(Method.java:498)
at org.testng.internal.MethodInvocationHelper.invokeMethod(MethodInvocationHelper.java:132)
at org.testng.internal.TestInvoker.invokeMethod(TestInvoker.java:599)
at org.testng.internal.TestInvoker.invokeTestMethod(TestInvoker.java:174)
at org.testng.internal.MethodRunner.runInSequence(MethodRunner.java:46)
at org.testng.internal.TestInvoker$MethodInvocationAgent.invoke(TestInvoker.java:822)
at org.testng.internal.TestInvoker.invokeTestMethods(TestInvoker.java:147)
at org.testng.internal.TestMethodWorker.invokeTestMethods(TestMethodWorker.java:146)
at org.testng.internal.TestMethodWorker.run(TestMethodWorker.java:128)
at java.util.ArrayList.forEach(ArrayList.java:1257)
at org.testng.TestRunner.privateRun(TestRunner.java:764)
at org.testng.TestRunner.run(TestRunner.java:585)
at org.testng.SuiteRunner.runTest(SuiteRunner.java:384)
at org.testng.SuiteRunner.access$000(SuiteRunner.java:28)
at org.testng.SuiteRunner$SuiteWorker.run(SuiteRunner.java:425)
at org.testng.internal.thread.ThreadUtil.lambda$execute$0(ThreadUtil.java:66)
at java.util.concurrent.FutureTask.run(FutureTask.java:266)
at java.util.concurrent.ThreadPoolExecutor.runWorker(ThreadPoolExecutor.java:1149)
at java.util.concurrent.ThreadPoolExecutor$Worker.run(ThreadPoolExecutor.java:624)
at java.lang.Thread.run(Thread.java:748)
]]>
            </full-stacktrace>
          </exception> <!-- java.lang.AssertionError -->
          <reporter-output>
          </reporter-output>
        </test-method> <!-- DivideNegativeandPostiveNumbers -->
        <test-method status="PASS" signature="DivideOneAndZero()[pri:0, instance:Acacemy.DivisionTests@4b553d26]" name="DivideOneAndZero" duration-ms="5181" started-at="2021-03-14T15:51:39 GMT" finished-at="2021-03-14T15:51:44 GMT">
          <reporter-output>
          </reporter-output>
        </test-method> <!-- DivideOneAndZero -->
        <test-method status="FAIL" signature="DivideZeroAndOne()[pri:0, instance:Acacemy.DivisionTests@4b553d26]" name="DivideZeroAndOne" duration-ms="5241" started-at="2021-03-14T15:51:44 GMT" finished-at="2021-03-14T15:51:49 GMT">
          <exception class="java.lang.AssertionError">
            <message>
              <![CDATA[expected [0] but found [1.0E-10]]]>
            </message>
            <full-stacktrace>
              <![CDATA[java.lang.AssertionError: expected [0] but found [1.0E-10]
at org.testng.Assert.fail(Assert.java:99)
at org.testng.Assert.failNotEquals(Assert.java:1037)
at org.testng.Assert.assertEqualsImpl(Assert.java:140)
at org.testng.Assert.assertEquals(Assert.java:122)
at org.testng.Assert.assertEquals(Assert.java:629)
at org.testng.Assert.assertEquals(Assert.java:639)
at Acacemy.DivisionTests.DivideZeroAndOne(DivisionTests.java:54)
at sun.reflect.NativeMethodAccessorImpl.invoke0(Native Method)
at sun.reflect.NativeMethodAccessorImpl.invoke(NativeMethodAccessorImpl.java:62)
at sun.reflect.DelegatingMethodAccessorImpl.invoke(DelegatingMethodAccessorImpl.java:43)
at java.lang.reflect.Method.invoke(Method.java:498)
at org.testng.internal.MethodInvocationHelper.invokeMethod(MethodInvocationHelper.java:132)
at org.testng.internal.TestInvoker.invokeMethod(TestInvoker.java:599)
at org.testng.internal.TestInvoker.invokeTestMethod(TestInvoker.java:174)
at org.testng.internal.MethodRunner.runInSequence(MethodRunner.java:46)
at org.testng.internal.TestInvoker$MethodInvocationAgent.invoke(TestInvoker.java:822)
at org.testng.internal.TestInvoker.invokeTestMethods(TestInvoker.java:147)
at org.testng.internal.TestMethodWorker.invokeTestMethods(TestMethodWorker.java:146)
at org.testng.internal.TestMethodWorker.run(TestMethodWorker.java:128)
at java.util.ArrayList.forEach(ArrayList.java:1257)
at org.testng.TestRunner.privateRun(TestRunner.java:764)
at org.testng.TestRunner.run(TestRunner.java:585)
at org.testng.SuiteRunner.runTest(SuiteRunner.java:384)
at org.testng.SuiteRunner.access$000(SuiteRunner.java:28)
at org.testng.SuiteRunner$SuiteWorker.run(SuiteRunner.java:425)
at org.testng.internal.thread.ThreadUtil.lambda$execute$0(ThreadUtil.java:66)
at java.util.concurrent.FutureTask.run(FutureTask.java:266)
at java.util.concurrent.ThreadPoolExecutor.runWorker(ThreadPoolExecutor.java:1149)
at java.util.concurrent.ThreadPoolExecutor$Worker.run(ThreadPoolExecutor.java:624)
at java.lang.Thread.run(Thread.java:748)
]]>
            </full-stacktrace>
          </exception> <!-- java.lang.AssertionError -->
          <reporter-output>
          </reporter-output>
        </test-method> <!-- DivideZeroAndOne -->
        <test-method status="PASS" signature="DivideZeroAndZero()[pri:0, instance:Acacemy.DivisionTests@4b553d26]" name="DivideZeroAndZero" duration-ms="5227" started-at="2021-03-14T15:51:50 GMT" finished-at="2021-03-14T15:51:55 GMT">
          <reporter-output>
          </reporter-output>
        </test-method> <!-- DivideZeroAndZero -->
        <test-method status="PASS" signature="Teardown()[pri:0, instance:Acacemy.DivisionTests@4b553d26]" name="Teardown" is-config="true" duration-ms="158" started-at="2021-03-14T15:51:55 GMT" finished-at="2021-03-14T15:51:55 GMT">
          <reporter-output>
          </reporter-output>
        </test-method> <!-- Teardown -->
      </class> <!-- Acacemy.DivisionTests -->
    </test> <!-- Division -->
    <test name="Subtraction" duration-ms="49648" started-at="2021-03-14T15:51:07 GMT" finished-at="2021-03-14T15:51:56 GMT">
      <class name="Acacemy.SubtractionTest">
        <test-method status="PASS" signature="initialization()[pri:0, instance:Acacemy.SubtractionTest@528931cf]" name="initialization" is-config="true" duration-ms="7475" started-at="2021-03-14T15:51:07 GMT" finished-at="2021-03-14T15:51:14 GMT">
          <reporter-output>
          </reporter-output>
        </test-method> <!-- initialization -->
        <test-method status="FAIL" signature="SubtractAscendRangeAndDescendRange()[pri:0, instance:Acacemy.SubtractionTest@528931cf]" name="SubtractAscendRangeAndDescendRange" duration-ms="7307" started-at="2021-03-14T15:51:14 GMT" finished-at="2021-03-14T15:51:21 GMT">
          <exception class="java.lang.AssertionError">
            <message>
              <![CDATA[expected [-55545] but found [190235.0000000001]]]>
            </message>
            <full-stacktrace>
              <![CDATA[java.lang.AssertionError: expected [-55545] but found [190235.0000000001]
at org.testng.Assert.fail(Assert.java:99)
at org.testng.Assert.failNotEquals(Assert.java:1037)
at org.testng.Assert.assertEqualsImpl(Assert.java:140)
at org.testng.Assert.assertEquals(Assert.java:122)
at org.testng.Assert.assertEquals(Assert.java:629)
at org.testng.Assert.assertEquals(Assert.java:639)
at Acacemy.SubtractionTest.SubtractAscendRangeAndDescendRange(SubtractionTest.java:33)
at sun.reflect.NativeMethodAccessorImpl.invoke0(Native Method)
at sun.reflect.NativeMethodAccessorImpl.invoke(NativeMethodAccessorImpl.java:62)
at sun.reflect.DelegatingMethodAccessorImpl.invoke(DelegatingMethodAccessorImpl.java:43)
at java.lang.reflect.Method.invoke(Method.java:498)
at org.testng.internal.MethodInvocationHelper.invokeMethod(MethodInvocationHelper.java:132)
at org.testng.internal.TestInvoker.invokeMethod(TestInvoker.java:599)
at org.testng.internal.TestInvoker.invokeTestMethod(TestInvoker.java:174)
at org.testng.internal.MethodRunner.runInSequence(MethodRunner.java:46)
at org.testng.internal.TestInvoker$MethodInvocationAgent.invoke(TestInvoker.java:822)
at org.testng.internal.TestInvoker.invokeTestMethods(TestInvoker.java:147)
at org.testng.internal.TestMethodWorker.invokeTestMethods(TestMethodWorker.java:146)
at org.testng.internal.TestMethodWorker.run(TestMethodWorker.java:128)
at java.util.ArrayList.forEach(ArrayList.java:1257)
at org.testng.TestRunner.privateRun(TestRunner.java:764)
at org.testng.TestRunner.run(TestRunner.java:585)
at org.testng.SuiteRunner.runTest(SuiteRunner.java:384)
at org.testng.SuiteRunner.access$000(SuiteRunner.java:28)
at org.testng.SuiteRunner$SuiteWorker.run(SuiteRunner.java:425)
at org.testng.internal.thread.ThreadUtil.lambda$execute$0(ThreadUtil.java:66)
at java.util.concurrent.FutureTask.run(FutureTask.java:266)
at java.util.concurrent.ThreadPoolExecutor.runWorker(ThreadPoolExecutor.java:1149)
at java.util.concurrent.ThreadPoolExecutor$Worker.run(ThreadPoolExecutor.java:624)
at java.lang.Thread.run(Thread.java:748)
]]>
            </full-stacktrace>
          </exception> <!-- java.lang.AssertionError -->
          <reporter-output>
          </reporter-output>
        </test-method> <!-- SubtractAscendRangeAndDescendRange -->
        <test-method status="FAIL" signature="SubtractBracketsFiveAndTwo()[pri:0, instance:Acacemy.SubtractionTest@528931cf]" name="SubtractBracketsFiveAndTwo" duration-ms="5679" started-at="2021-03-14T15:51:22 GMT" description="Subtractition test of zero and minus one" finished-at="2021-03-14T15:51:27 GMT">
          <exception class="java.lang.AssertionError">
            <message>
              <![CDATA[expected [-7] but found [13.5000000001]]]>
            </message>
            <full-stacktrace>
              <![CDATA[java.lang.AssertionError: expected [-7] but found [13.5000000001]
at org.testng.Assert.fail(Assert.java:99)
at org.testng.Assert.failNotEquals(Assert.java:1037)
at org.testng.Assert.assertEqualsImpl(Assert.java:140)
at org.testng.Assert.assertEquals(Assert.java:122)
at org.testng.Assert.assertEquals(Assert.java:629)
at org.testng.Assert.assertEquals(Assert.java:639)
at Acacemy.SubtractionTest.SubtractBracketsFiveAndTwo(SubtractionTest.java:67)
at sun.reflect.NativeMethodAccessorImpl.invoke0(Native Method)
at sun.reflect.NativeMethodAccessorImpl.invoke(NativeMethodAccessorImpl.java:62)
at sun.reflect.DelegatingMethodAccessorImpl.invoke(DelegatingMethodAccessorImpl.java:43)
at java.lang.reflect.Method.invoke(Method.java:498)
at org.testng.internal.MethodInvocationHelper.invokeMethod(MethodInvocationHelper.java:132)
at org.testng.internal.TestInvoker.invokeMethod(TestInvoker.java:599)
at org.testng.internal.TestInvoker.invokeTestMethod(TestInvoker.java:174)
at org.testng.internal.MethodRunner.runInSequence(MethodRunner.java:46)
at org.testng.internal.TestInvoker$MethodInvocationAgent.invoke(TestInvoker.java:822)
at org.testng.internal.TestInvoker.invokeTestMethods(TestInvoker.java:147)
at org.testng.internal.TestMethodWorker.invokeTestMethods(TestMethodWorker.java:146)
at org.testng.internal.TestMethodWorker.run(TestMethodWorker.java:128)
at java.util.ArrayList.forEach(ArrayList.java:1257)
at org.testng.TestRunner.privateRun(TestRunner.java:764)
at org.testng.TestRunner.run(TestRunner.java:585)
at org.testng.SuiteRunner.runTest(SuiteRunner.java:384)
at org.testng.SuiteRunner.access$000(SuiteRunner.java:28)
at org.testng.SuiteRunner$SuiteWorker.run(SuiteRunner.java:425)
at org.testng.internal.thread.ThreadUtil.lambda$execute$0(ThreadUtil.java:66)
at java.util.concurrent.FutureTask.run(FutureTask.java:266)
at java.util.concurrent.ThreadPoolExecutor.runWorker(ThreadPoolExecutor.java:1149)
at java.util.concurrent.ThreadPoolExecutor$Worker.run(ThreadPoolExecutor.java:624)
at java.lang.Thread.run(Thread.java:748)
]]>
            </full-stacktrace>
          </exception> <!-- java.lang.AssertionError -->
          <reporter-output>
          </reporter-output>
        </test-method> <!-- SubtractBracketsFiveAndTwo -->
        <test-method status="FAIL" signature="SubtractDecimalTwoPointTwoMinusOne()[pri:0, instance:Acacemy.SubtractionTest@528931cf]" name="SubtractDecimalTwoPointTwoMinusOne" duration-ms="5521" started-at="2021-03-14T15:51:28 GMT" description="Subtractition test of zero and minus one" finished-at="2021-03-14T15:51:33 GMT">
          <exception class="java.lang.AssertionError">
            <message>
              <![CDATA[expected [3.2] but found [23.220000000099997]]]>
            </message>
            <full-stacktrace>
              <![CDATA[java.lang.AssertionError: expected [3.2] but found [23.220000000099997]
at org.testng.Assert.fail(Assert.java:99)
at org.testng.Assert.failNotEquals(Assert.java:1037)
at org.testng.Assert.assertEqualsImpl(Assert.java:140)
at org.testng.Assert.assertEquals(Assert.java:122)
at org.testng.Assert.assertEquals(Assert.java:629)
at org.testng.Assert.assertEquals(Assert.java:639)
at Acacemy.SubtractionTest.SubtractDecimalTwoPointTwoMinusOne(SubtractionTest.java:73)
at sun.reflect.NativeMethodAccessorImpl.invoke0(Native Method)
at sun.reflect.NativeMethodAccessorImpl.invoke(NativeMethodAccessorImpl.java:62)
at sun.reflect.DelegatingMethodAccessorImpl.invoke(DelegatingMethodAccessorImpl.java:43)
at java.lang.reflect.Method.invoke(Method.java:498)
at org.testng.internal.MethodInvocationHelper.invokeMethod(MethodInvocationHelper.java:132)
at org.testng.internal.TestInvoker.invokeMethod(TestInvoker.java:599)
at org.testng.internal.TestInvoker.invokeTestMethod(TestInvoker.java:174)
at org.testng.internal.MethodRunner.runInSequence(MethodRunner.java:46)
at org.testng.internal.TestInvoker$MethodInvocationAgent.invoke(TestInvoker.java:822)
at org.testng.internal.TestInvoker.invokeTestMethods(TestInvoker.java:147)
at org.testng.internal.TestMethodWorker.invokeTestMethods(TestMethodWorker.java:146)
at org.testng.internal.TestMethodWorker.run(TestMethodWorker.java:128)
at java.util.ArrayList.forEach(ArrayList.java:1257)
at org.testng.TestRunner.privateRun(TestRunner.java:764)
at org.testng.TestRunner.run(TestRunner.java:585)
at org.testng.SuiteRunner.runTest(SuiteRunner.java:384)
at org.testng.SuiteRunner.access$000(SuiteRunner.java:28)
at org.testng.SuiteRunner$SuiteWorker.run(SuiteRunner.java:425)
at org.testng.internal.thread.ThreadUtil.lambda$execute$0(ThreadUtil.java:66)
at java.util.concurrent.FutureTask.run(FutureTask.java:266)
at java.util.concurrent.ThreadPoolExecutor.runWorker(ThreadPoolExecutor.java:1149)
at java.util.concurrent.ThreadPoolExecutor$Worker.run(ThreadPoolExecutor.java:624)
at java.lang.Thread.run(Thread.java:748)
]]>
            </full-stacktrace>
          </exception> <!-- java.lang.AssertionError -->
          <reporter-output>
          </reporter-output>
        </test-method> <!-- SubtractDecimalTwoPointTwoMinusOne -->
        <test-method status="FAIL" signature="SubtractMorethanTwoNumbers()[pri:0, instance:Acacemy.SubtractionTest@528931cf]" name="SubtractMorethanTwoNumbers" duration-ms="5347" started-at="2021-03-14T15:51:34 GMT" finished-at="2021-03-14T15:51:39 GMT">
          <exception class="java.lang.AssertionError">
            <message>
              <![CDATA[expected [3] but found [62.5000000001]]]>
            </message>
            <full-stacktrace>
              <![CDATA[java.lang.AssertionError: expected [3] but found [62.5000000001]
at org.testng.Assert.fail(Assert.java:99)
at org.testng.Assert.failNotEquals(Assert.java:1037)
at org.testng.Assert.assertEqualsImpl(Assert.java:140)
at org.testng.Assert.assertEquals(Assert.java:122)
at org.testng.Assert.assertEquals(Assert.java:629)
at org.testng.Assert.assertEquals(Assert.java:639)
at Acacemy.SubtractionTest.SubtractMorethanTwoNumbers(SubtractionTest.java:80)
at sun.reflect.NativeMethodAccessorImpl.invoke0(Native Method)
at sun.reflect.NativeMethodAccessorImpl.invoke(NativeMethodAccessorImpl.java:62)
at sun.reflect.DelegatingMethodAccessorImpl.invoke(DelegatingMethodAccessorImpl.java:43)
at java.lang.reflect.Method.invoke(Method.java:498)
at org.testng.internal.MethodInvocationHelper.invokeMethod(MethodInvocationHelper.java:132)
at org.testng.internal.TestInvoker.invokeMethod(TestInvoker.java:599)
at org.testng.internal.TestInvoker.invokeTestMethod(TestInvoker.java:174)
at org.testng.internal.MethodRunner.runInSequence(MethodRunner.java:46)
at org.testng.internal.TestInvoker$MethodInvocationAgent.invoke(TestInvoker.java:822)
at org.testng.internal.TestInvoker.invokeTestMethods(TestInvoker.java:147)
at org.testng.internal.TestMethodWorker.invokeTestMethods(TestMethodWorker.java:146)
at org.testng.internal.TestMethodWorker.run(TestMethodWorker.java:128)
at java.util.ArrayList.forEach(ArrayList.java:1257)
at org.testng.TestRunner.privateRun(TestRunner.java:764)
at org.testng.TestRunner.run(TestRunner.java:585)
at org.testng.SuiteRunner.runTest(SuiteRunner.java:384)
at org.testng.SuiteRunner.access$000(SuiteRunner.java:28)
at org.testng.SuiteRunner$SuiteWorker.run(SuiteRunner.java:425)
at org.testng.internal.thread.ThreadUtil.lambda$execute$0(ThreadUtil.java:66)
at java.util.concurrent.FutureTask.run(FutureTask.java:266)
at java.util.concurrent.ThreadPoolExecutor.runWorker(ThreadPoolExecutor.java:1149)
at java.util.concurrent.ThreadPoolExecutor$Worker.run(ThreadPoolExecutor.java:624)
at java.lang.Thread.run(Thread.java:748)
]]>
            </full-stacktrace>
          </exception> <!-- java.lang.AssertionError -->
          <reporter-output>
          </reporter-output>
        </test-method> <!-- SubtractMorethanTwoNumbers -->
        <test-method status="FAIL" signature="SubtractOneAndZero()[pri:0, instance:Acacemy.SubtractionTest@528931cf]" name="SubtractOneAndZero" duration-ms="5223" started-at="2021-03-14T15:51:39 GMT" finished-at="2021-03-14T15:51:45 GMT">
          <exception class="java.lang.AssertionError">
            <message>
              <![CDATA[expected [-6] but found [8.0000000001]]]>
            </message>
            <full-stacktrace>
              <![CDATA[java.lang.AssertionError: expected [-6] but found [8.0000000001]
at org.testng.Assert.fail(Assert.java:99)
at org.testng.Assert.failNotEquals(Assert.java:1037)
at org.testng.Assert.assertEqualsImpl(Assert.java:140)
at org.testng.Assert.assertEquals(Assert.java:122)
at org.testng.Assert.assertEquals(Assert.java:629)
at org.testng.Assert.assertEquals(Assert.java:639)
at Acacemy.SubtractionTest.SubtractOneAndZero(SubtractionTest.java:61)
at sun.reflect.NativeMethodAccessorImpl.invoke0(Native Method)
at sun.reflect.NativeMethodAccessorImpl.invoke(NativeMethodAccessorImpl.java:62)
at sun.reflect.DelegatingMethodAccessorImpl.invoke(DelegatingMethodAccessorImpl.java:43)
at java.lang.reflect.Method.invoke(Method.java:498)
at org.testng.internal.MethodInvocationHelper.invokeMethod(MethodInvocationHelper.java:132)
at org.testng.internal.TestInvoker.invokeMethod(TestInvoker.java:599)
at org.testng.internal.TestInvoker.invokeTestMethod(TestInvoker.java:174)
at org.testng.internal.MethodRunner.runInSequence(MethodRunner.java:46)
at org.testng.internal.TestInvoker$MethodInvocationAgent.invoke(TestInvoker.java:822)
at org.testng.internal.TestInvoker.invokeTestMethods(TestInvoker.java:147)
at org.testng.internal.TestMethodWorker.invokeTestMethods(TestMethodWorker.java:146)
at org.testng.internal.TestMethodWorker.run(TestMethodWorker.java:128)
at java.util.ArrayList.forEach(ArrayList.java:1257)
at org.testng.TestRunner.privateRun(TestRunner.java:764)
at org.testng.TestRunner.run(TestRunner.java:585)
at org.testng.SuiteRunner.runTest(SuiteRunner.java:384)
at org.testng.SuiteRunner.access$000(SuiteRunner.java:28)
at org.testng.SuiteRunner$SuiteWorker.run(SuiteRunner.java:425)
at org.testng.internal.thread.ThreadUtil.lambda$execute$0(ThreadUtil.java:66)
at java.util.concurrent.FutureTask.run(FutureTask.java:266)
at java.util.concurrent.ThreadPoolExecutor.runWorker(ThreadPoolExecutor.java:1149)
at java.util.concurrent.ThreadPoolExecutor$Worker.run(ThreadPoolExecutor.java:624)
at java.lang.Thread.run(Thread.java:748)
]]>
            </full-stacktrace>
          </exception> <!-- java.lang.AssertionError -->
          <reporter-output>
          </reporter-output>
        </test-method> <!-- SubtractOneAndZero -->
        <test-method status="FAIL" signature="SubtractZeroAndOne()[pri:0, instance:Acacemy.SubtractionTest@528931cf]" name="SubtractZeroAndOne" duration-ms="5224" started-at="2021-03-14T15:51:45 GMT" finished-at="2021-03-14T15:51:50 GMT">
          <exception class="java.lang.AssertionError">
            <message>
              <![CDATA[expected [2] but found [4.0000000001]]]>
            </message>
            <full-stacktrace>
              <![CDATA[java.lang.AssertionError: expected [2] but found [4.0000000001]
at org.testng.Assert.fail(Assert.java:99)
at org.testng.Assert.failNotEquals(Assert.java:1037)
at org.testng.Assert.assertEqualsImpl(Assert.java:140)
at org.testng.Assert.assertEquals(Assert.java:122)
at org.testng.Assert.assertEquals(Assert.java:629)
at org.testng.Assert.assertEquals(Assert.java:639)
at Acacemy.SubtractionTest.SubtractZeroAndOne(SubtractionTest.java:51)
at sun.reflect.NativeMethodAccessorImpl.invoke0(Native Method)
at sun.reflect.NativeMethodAccessorImpl.invoke(NativeMethodAccessorImpl.java:62)
at sun.reflect.DelegatingMethodAccessorImpl.invoke(DelegatingMethodAccessorImpl.java:43)
at java.lang.reflect.Method.invoke(Method.java:498)
at org.testng.internal.MethodInvocationHelper.invokeMethod(MethodInvocationHelper.java:132)
at org.testng.internal.TestInvoker.invokeMethod(TestInvoker.java:599)
at org.testng.internal.TestInvoker.invokeTestMethod(TestInvoker.java:174)
at org.testng.internal.MethodRunner.runInSequence(MethodRunner.java:46)
at org.testng.internal.TestInvoker$MethodInvocationAgent.invoke(TestInvoker.java:822)
at org.testng.internal.TestInvoker.invokeTestMethods(TestInvoker.java:147)
at org.testng.internal.TestMethodWorker.invokeTestMethods(TestMethodWorker.java:146)
at org.testng.internal.TestMethodWorker.run(TestMethodWorker.java:128)
at java.util.ArrayList.forEach(ArrayList.java:1257)
at org.testng.TestRunner.privateRun(TestRunner.java:764)
at org.testng.TestRunner.run(TestRunner.java:585)
at org.testng.SuiteRunner.runTest(SuiteRunner.java:384)
at org.testng.SuiteRunner.access$000(SuiteRunner.java:28)
at org.testng.SuiteRunner$SuiteWorker.run(SuiteRunner.java:425)
at org.testng.internal.thread.ThreadUtil.lambda$execute$0(ThreadUtil.java:66)
at java.util.concurrent.FutureTask.run(FutureTask.java:266)
at java.util.concurrent.ThreadPoolExecutor.runWorker(ThreadPoolExecutor.java:1149)
at java.util.concurrent.ThreadPoolExecutor$Worker.run(ThreadPoolExecutor.java:624)
at java.lang.Thread.run(Thread.java:748)
]]>
            </full-stacktrace>
          </exception> <!-- java.lang.AssertionError -->
          <reporter-output>
          </reporter-output>
        </test-method> <!-- SubtractZeroAndOne -->
        <test-method status="FAIL" signature="SubtractZeroAndZero()[pri:0, instance:Acacemy.SubtractionTest@528931cf]" name="SubtractZeroAndZero" duration-ms="5256" started-at="2021-03-14T15:51:50 GMT" finished-at="2021-03-14T15:51:56 GMT">
          <exception class="java.lang.AssertionError">
            <message>
              <![CDATA[expected [0] but found [2.0000000001]]]>
            </message>
            <full-stacktrace>
              <![CDATA[java.lang.AssertionError: expected [0] but found [2.0000000001]
at org.testng.Assert.fail(Assert.java:99)
at org.testng.Assert.failNotEquals(Assert.java:1037)
at org.testng.Assert.assertEqualsImpl(Assert.java:140)
at org.testng.Assert.assertEquals(Assert.java:122)
at org.testng.Assert.assertEquals(Assert.java:629)
at org.testng.Assert.assertEquals(Assert.java:639)
at Acacemy.SubtractionTest.SubtractZeroAndZero(SubtractionTest.java:40)
at sun.reflect.NativeMethodAccessorImpl.invoke0(Native Method)
at sun.reflect.NativeMethodAccessorImpl.invoke(NativeMethodAccessorImpl.java:62)
at sun.reflect.DelegatingMethodAccessorImpl.invoke(DelegatingMethodAccessorImpl.java:43)
at java.lang.reflect.Method.invoke(Method.java:498)
at org.testng.internal.MethodInvocationHelper.invokeMethod(MethodInvocationHelper.java:132)
at org.testng.internal.TestInvoker.invokeMethod(TestInvoker.java:599)
at org.testng.internal.TestInvoker.invokeTestMethod(TestInvoker.java:174)
at org.testng.internal.MethodRunner.runInSequence(MethodRunner.java:46)
at org.testng.internal.TestInvoker$MethodInvocationAgent.invoke(TestInvoker.java:822)
at org.testng.internal.TestInvoker.invokeTestMethods(TestInvoker.java:147)
at org.testng.internal.TestMethodWorker.invokeTestMethods(TestMethodWorker.java:146)
at org.testng.internal.TestMethodWorker.run(TestMethodWorker.java:128)
at java.util.ArrayList.forEach(ArrayList.java:1257)
at org.testng.TestRunner.privateRun(TestRunner.java:764)
at org.testng.TestRunner.run(TestRunner.java:585)
at org.testng.SuiteRunner.runTest(SuiteRunner.java:384)
at org.testng.SuiteRunner.access$000(SuiteRunner.java:28)
at org.testng.SuiteRunner$SuiteWorker.run(SuiteRunner.java:425)
at org.testng.internal.thread.ThreadUtil.lambda$execute$0(ThreadUtil.java:66)
at java.util.concurrent.FutureTask.run(FutureTask.java:266)
at java.util.concurrent.ThreadPoolExecutor.runWorker(ThreadPoolExecutor.java:1149)
at java.util.concurrent.ThreadPoolExecutor$Worker.run(ThreadPoolExecutor.java:624)
at java.lang.Thread.run(Thread.java:748)
]]>
            </full-stacktrace>
          </exception> <!-- java.lang.AssertionError -->
          <reporter-output>
          </reporter-output>
        </test-method> <!-- SubtractZeroAndZero -->
        <test-method status="PASS" signature="Teardown()[pri:0, instance:Acacemy.SubtractionTest@528931cf]" name="Teardown" is-config="true" duration-ms="111" started-at="2021-03-14T15:51:56 GMT" finished-at="2021-03-14T15:51:56 GMT">
          <reporter-output>
          </reporter-output>
        </test-method> <!-- Teardown -->
      </class> <!-- Acacemy.SubtractionTest -->
    </test> <!-- Subtraction -->
    <test name="Multiplication" duration-ms="61705" started-at="2021-03-14T15:51:07 GMT" finished-at="2021-03-14T15:52:08 GMT">
      <class name="Acacemy.multiplicationTests">
        <test-method status="PASS" signature="initialization()[pri:0, instance:Acacemy.multiplicationTests@7a765367]" name="initialization" is-config="true" duration-ms="7556" started-at="2021-03-14T15:51:07 GMT" finished-at="2021-03-14T15:51:14 GMT">
          <reporter-output>
          </reporter-output>
        </test-method> <!-- initialization -->
        <test-method status="FAIL" signature="MultiplyAscendRangeAndDescendRange()[pri:0, instance:Acacemy.multiplicationTests@7a765367]" name="MultiplyAscendRangeAndDescendRange" duration-ms="7088" started-at="2021-03-14T15:51:14 GMT" finished-at="2021-03-14T15:51:21 GMT">
          <exception class="java.lang.AssertionError">
            <message>
              <![CDATA[expected [38102050.0] but found [8.37389205E9]]]>
            </message>
            <full-stacktrace>
              <![CDATA[java.lang.AssertionError: expected [38102050.0] but found [8.37389205E9]
at org.testng.Assert.fail(Assert.java:99)
at org.testng.Assert.failNotEquals(Assert.java:1037)
at org.testng.Assert.assertEqualsImpl(Assert.java:140)
at org.testng.Assert.assertEquals(Assert.java:122)
at org.testng.Assert.assertEquals(Assert.java:629)
at org.testng.Assert.assertEquals(Assert.java:639)
at Acacemy.multiplicationTests.MultiplyAscendRangeAndDescendRange(multiplicationTests.java:28)
at sun.reflect.NativeMethodAccessorImpl.invoke0(Native Method)
at sun.reflect.NativeMethodAccessorImpl.invoke(NativeMethodAccessorImpl.java:62)
at sun.reflect.DelegatingMethodAccessorImpl.invoke(DelegatingMethodAccessorImpl.java:43)
at java.lang.reflect.Method.invoke(Method.java:498)
at org.testng.internal.MethodInvocationHelper.invokeMethod(MethodInvocationHelper.java:132)
at org.testng.internal.TestInvoker.invokeMethod(TestInvoker.java:599)
at org.testng.internal.TestInvoker.invokeTestMethod(TestInvoker.java:174)
at org.testng.internal.MethodRunner.runInSequence(MethodRunner.java:46)
at org.testng.internal.TestInvoker$MethodInvocationAgent.invoke(TestInvoker.java:822)
at org.testng.internal.TestInvoker.invokeTestMethods(TestInvoker.java:147)
at org.testng.internal.TestMethodWorker.invokeTestMethods(TestMethodWorker.java:146)
at org.testng.internal.TestMethodWorker.run(TestMethodWorker.java:128)
at java.util.ArrayList.forEach(ArrayList.java:1257)
at org.testng.TestRunner.privateRun(TestRunner.java:764)
at org.testng.TestRunner.run(TestRunner.java:585)
at org.testng.SuiteRunner.runTest(SuiteRunner.java:384)
at org.testng.SuiteRunner.access$000(SuiteRunner.java:28)
at org.testng.SuiteRunner$SuiteWorker.run(SuiteRunner.java:425)
at org.testng.internal.thread.ThreadUtil.lambda$execute$0(ThreadUtil.java:66)
at java.util.concurrent.FutureTask.run(FutureTask.java:266)
at java.util.concurrent.ThreadPoolExecutor.runWorker(ThreadPoolExecutor.java:1149)
at java.util.concurrent.ThreadPoolExecutor$Worker.run(ThreadPoolExecutor.java:624)
at java.lang.Thread.run(Thread.java:748)
]]>
            </full-stacktrace>
          </exception> <!-- java.lang.AssertionError -->
          <reporter-output>
          </reporter-output>
        </test-method> <!-- MultiplyAscendRangeAndDescendRange -->
        <test-method status="FAIL" signature="MultiplyDecimalTwoPointTwoMinusOne()[pri:0, instance:Acacemy.multiplicationTests@7a765367]" name="MultiplyDecimalTwoPointTwoMinusOne" duration-ms="5807" started-at="2021-03-14T15:51:22 GMT" description="Multiplyition test of zero and minus one" finished-at="2021-03-14T15:51:27 GMT">
          <exception class="java.lang.AssertionError">
            <message>
              <![CDATA[expected [11.25] but found [11.2500000001]]]>
            </message>
            <full-stacktrace>
              <![CDATA[java.lang.AssertionError: expected [11.25] but found [11.2500000001]
at org.testng.Assert.fail(Assert.java:99)
at org.testng.Assert.failNotEquals(Assert.java:1037)
at org.testng.Assert.assertEqualsImpl(Assert.java:140)
at org.testng.Assert.assertEquals(Assert.java:122)
at org.testng.Assert.assertEquals(Assert.java:629)
at org.testng.Assert.assertEquals(Assert.java:639)
at Acacemy.multiplicationTests.MultiplyDecimalTwoPointTwoMinusOne(multiplicationTests.java:87)
at sun.reflect.NativeMethodAccessorImpl.invoke0(Native Method)
at sun.reflect.NativeMethodAccessorImpl.invoke(NativeMethodAccessorImpl.java:62)
at sun.reflect.DelegatingMethodAccessorImpl.invoke(DelegatingMethodAccessorImpl.java:43)
at java.lang.reflect.Method.invoke(Method.java:498)
at org.testng.internal.MethodInvocationHelper.invokeMethod(MethodInvocationHelper.java:132)
at org.testng.internal.TestInvoker.invokeMethod(TestInvoker.java:599)
at org.testng.internal.TestInvoker.invokeTestMethod(TestInvoker.java:174)
at org.testng.internal.MethodRunner.runInSequence(MethodRunner.java:46)
at org.testng.internal.TestInvoker$MethodInvocationAgent.invoke(TestInvoker.java:822)
at org.testng.internal.TestInvoker.invokeTestMethods(TestInvoker.java:147)
at org.testng.internal.TestMethodWorker.invokeTestMethods(TestMethodWorker.java:146)
at org.testng.internal.TestMethodWorker.run(TestMethodWorker.java:128)
at java.util.ArrayList.forEach(ArrayList.java:1257)
at org.testng.TestRunner.privateRun(TestRunner.java:764)
at org.testng.TestRunner.run(TestRunner.java:585)
at org.testng.SuiteRunner.runTest(SuiteRunner.java:384)
at org.testng.SuiteRunner.access$000(SuiteRunner.java:28)
at org.testng.SuiteRunner$SuiteWorker.run(SuiteRunner.java:425)
at org.testng.internal.thread.ThreadUtil.lambda$execute$0(ThreadUtil.java:66)
at java.util.concurrent.FutureTask.run(FutureTask.java:266)
at java.util.concurrent.ThreadPoolExecutor.runWorker(ThreadPoolExecutor.java:1149)
at java.util.concurrent.ThreadPoolExecutor$Worker.run(ThreadPoolExecutor.java:624)
at java.lang.Thread.run(Thread.java:748)
]]>
            </full-stacktrace>
          </exception> <!-- java.lang.AssertionError -->
          <reporter-output>
          </reporter-output>
        </test-method> <!-- MultiplyDecimalTwoPointTwoMinusOne -->
        <test-method status="FAIL" signature="MultiplyMorethanTwoBigNumbers()[pri:0, instance:Acacemy.multiplicationTests@7a765367]" name="MultiplyMorethanTwoBigNumbers" duration-ms="5964" started-at="2021-03-14T15:51:28 GMT" finished-at="2021-03-14T15:51:34 GMT">
          <exception class="java.lang.AssertionError">
            <message>
              <![CDATA[expected [6.789199772124E12] but found [6.7892332847724E13]]]>
            </message>
            <full-stacktrace>
              <![CDATA[java.lang.AssertionError: expected [6.789199772124E12] but found [6.7892332847724E13]
at org.testng.Assert.fail(Assert.java:99)
at org.testng.Assert.failNotEquals(Assert.java:1037)
at org.testng.Assert.assertEqualsImpl(Assert.java:140)
at org.testng.Assert.assertEquals(Assert.java:122)
at org.testng.Assert.assertEquals(Assert.java:629)
at org.testng.Assert.assertEquals(Assert.java:639)
at Acacemy.multiplicationTests.MultiplyMorethanTwoBigNumbers(multiplicationTests.java:47)
at sun.reflect.NativeMethodAccessorImpl.invoke0(Native Method)
at sun.reflect.NativeMethodAccessorImpl.invoke(NativeMethodAccessorImpl.java:62)
at sun.reflect.DelegatingMethodAccessorImpl.invoke(DelegatingMethodAccessorImpl.java:43)
at java.lang.reflect.Method.invoke(Method.java:498)
at org.testng.internal.MethodInvocationHelper.invokeMethod(MethodInvocationHelper.java:132)
at org.testng.internal.TestInvoker.invokeMethod(TestInvoker.java:599)
at org.testng.internal.TestInvoker.invokeTestMethod(TestInvoker.java:174)
at org.testng.internal.MethodRunner.runInSequence(MethodRunner.java:46)
at org.testng.internal.TestInvoker$MethodInvocationAgent.invoke(TestInvoker.java:822)
at org.testng.internal.TestInvoker.invokeTestMethods(TestInvoker.java:147)
at org.testng.internal.TestMethodWorker.invokeTestMethods(TestMethodWorker.java:146)
at org.testng.internal.TestMethodWorker.run(TestMethodWorker.java:128)
at java.util.ArrayList.forEach(ArrayList.java:1257)
at org.testng.TestRunner.privateRun(TestRunner.java:764)
at org.testng.TestRunner.run(TestRunner.java:585)
at org.testng.SuiteRunner.runTest(SuiteRunner.java:384)
at org.testng.SuiteRunner.access$000(SuiteRunner.java:28)
at org.testng.SuiteRunner$SuiteWorker.run(SuiteRunner.java:425)
at org.testng.internal.thread.ThreadUtil.lambda$execute$0(ThreadUtil.java:66)
at java.util.concurrent.FutureTask.run(FutureTask.java:266)
at java.util.concurrent.ThreadPoolExecutor.runWorker(ThreadPoolExecutor.java:1149)
at java.util.concurrent.ThreadPoolExecutor$Worker.run(ThreadPoolExecutor.java:624)
at java.lang.Thread.run(Thread.java:748)
]]>
            </full-stacktrace>
          </exception> <!-- java.lang.AssertionError -->
          <reporter-output>
          </reporter-output>
        </test-method> <!-- MultiplyMorethanTwoBigNumbers -->
        <test-method status="FAIL" signature="MultiplyMorethanTwoNumbers()[pri:0, instance:Acacemy.multiplicationTests@7a765367]" name="MultiplyMorethanTwoNumbers" duration-ms="5338" started-at="2021-03-14T15:51:34 GMT" finished-at="2021-03-14T15:51:39 GMT">
          <exception class="java.lang.AssertionError">
            <message>
              <![CDATA[expected [216.0] but found [2376.0000000001]]]>
            </message>
            <full-stacktrace>
              <![CDATA[java.lang.AssertionError: expected [216.0] but found [2376.0000000001]
at org.testng.Assert.fail(Assert.java:99)
at org.testng.Assert.failNotEquals(Assert.java:1037)
at org.testng.Assert.assertEqualsImpl(Assert.java:140)
at org.testng.Assert.assertEquals(Assert.java:122)
at org.testng.Assert.assertEquals(Assert.java:629)
at org.testng.Assert.assertEquals(Assert.java:639)
at Acacemy.multiplicationTests.MultiplyMorethanTwoNumbers(multiplicationTests.java:41)
at sun.reflect.NativeMethodAccessorImpl.invoke0(Native Method)
at sun.reflect.NativeMethodAccessorImpl.invoke(NativeMethodAccessorImpl.java:62)
at sun.reflect.DelegatingMethodAccessorImpl.invoke(DelegatingMethodAccessorImpl.java:43)
at java.lang.reflect.Method.invoke(Method.java:498)
at org.testng.internal.MethodInvocationHelper.invokeMethod(MethodInvocationHelper.java:132)
at org.testng.internal.TestInvoker.invokeMethod(TestInvoker.java:599)
at org.testng.internal.TestInvoker.invokeTestMethod(TestInvoker.java:174)
at org.testng.internal.MethodRunner.runInSequence(MethodRunner.java:46)
at org.testng.internal.TestInvoker$MethodInvocationAgent.invoke(TestInvoker.java:822)
at org.testng.internal.TestInvoker.invokeTestMethods(TestInvoker.java:147)
at org.testng.internal.TestMethodWorker.invokeTestMethods(TestMethodWorker.java:146)
at org.testng.internal.TestMethodWorker.run(TestMethodWorker.java:128)
at java.util.ArrayList.forEach(ArrayList.java:1257)
at org.testng.TestRunner.privateRun(TestRunner.java:764)
at org.testng.TestRunner.run(TestRunner.java:585)
at org.testng.SuiteRunner.runTest(SuiteRunner.java:384)
at org.testng.SuiteRunner.access$000(SuiteRunner.java:28)
at org.testng.SuiteRunner$SuiteWorker.run(SuiteRunner.java:425)
at org.testng.internal.thread.ThreadUtil.lambda$execute$0(ThreadUtil.java:66)
at java.util.concurrent.FutureTask.run(FutureTask.java:266)
at java.util.concurrent.ThreadPoolExecutor.runWorker(ThreadPoolExecutor.java:1149)
at java.util.concurrent.ThreadPoolExecutor$Worker.run(ThreadPoolExecutor.java:624)
at java.lang.Thread.run(Thread.java:748)
]]>
            </full-stacktrace>
          </exception> <!-- java.lang.AssertionError -->
          <reporter-output>
          </reporter-output>
        </test-method> <!-- MultiplyMorethanTwoNumbers -->
        <test-method status="FAIL" signature="MultiplyNegativeandPostiveNumbers()[pri:0, instance:Acacemy.multiplicationTests@7a765367]" name="MultiplyNegativeandPostiveNumbers" duration-ms="5329" started-at="2021-03-14T15:51:40 GMT" description="Multiplyition test of zero and minus one" finished-at="2021-03-14T15:51:45 GMT">
          <exception class="java.lang.AssertionError">
            <message>
              <![CDATA[expected [-35.0] but found [35.0000000001]]]>
            </message>
            <full-stacktrace>
              <![CDATA[java.lang.AssertionError: expected [-35.0] but found [35.0000000001]
at org.testng.Assert.fail(Assert.java:99)
at org.testng.Assert.failNotEquals(Assert.java:1037)
at org.testng.Assert.assertEqualsImpl(Assert.java:140)
at org.testng.Assert.assertEquals(Assert.java:122)
at org.testng.Assert.assertEquals(Assert.java:629)
at org.testng.Assert.assertEquals(Assert.java:639)
at Acacemy.multiplicationTests.MultiplyNegativeandPostiveNumbers(multiplicationTests.java:81)
at sun.reflect.NativeMethodAccessorImpl.invoke0(Native Method)
at sun.reflect.NativeMethodAccessorImpl.invoke(NativeMethodAccessorImpl.java:62)
at sun.reflect.DelegatingMethodAccessorImpl.invoke(DelegatingMethodAccessorImpl.java:43)
at java.lang.reflect.Method.invoke(Method.java:498)
at org.testng.internal.MethodInvocationHelper.invokeMethod(MethodInvocationHelper.java:132)
at org.testng.internal.TestInvoker.invokeMethod(TestInvoker.java:599)
at org.testng.internal.TestInvoker.invokeTestMethod(TestInvoker.java:174)
at org.testng.internal.MethodRunner.runInSequence(MethodRunner.java:46)
at org.testng.internal.TestInvoker$MethodInvocationAgent.invoke(TestInvoker.java:822)
at org.testng.internal.TestInvoker.invokeTestMethods(TestInvoker.java:147)
at org.testng.internal.TestMethodWorker.invokeTestMethods(TestMethodWorker.java:146)
at org.testng.internal.TestMethodWorker.run(TestMethodWorker.java:128)
at java.util.ArrayList.forEach(ArrayList.java:1257)
at org.testng.TestRunner.privateRun(TestRunner.java:764)
at org.testng.TestRunner.run(TestRunner.java:585)
at org.testng.SuiteRunner.runTest(SuiteRunner.java:384)
at org.testng.SuiteRunner.access$000(SuiteRunner.java:28)
at org.testng.SuiteRunner$SuiteWorker.run(SuiteRunner.java:425)
at org.testng.internal.thread.ThreadUtil.lambda$execute$0(ThreadUtil.java:66)
at java.util.concurrent.FutureTask.run(FutureTask.java:266)
at java.util.concurrent.ThreadPoolExecutor.runWorker(ThreadPoolExecutor.java:1149)
at java.util.concurrent.ThreadPoolExecutor$Worker.run(ThreadPoolExecutor.java:624)
at java.lang.Thread.run(Thread.java:748)
]]>
            </full-stacktrace>
          </exception> <!-- java.lang.AssertionError -->
          <reporter-output>
          </reporter-output>
        </test-method> <!-- MultiplyNegativeandPostiveNumbers -->
        <test-method status="FAIL" signature="MultiplyOneAndZero()[pri:0, instance:Acacemy.multiplicationTests@7a765367]" name="MultiplyOneAndZero" duration-ms="5213" started-at="2021-03-14T15:51:45 GMT" finished-at="2021-03-14T15:51:50 GMT">
          <exception class="java.lang.AssertionError">
            <message>
              <![CDATA[expected [0] but found [1.0E-10]]]>
            </message>
            <full-stacktrace>
              <![CDATA[java.lang.AssertionError: expected [0] but found [1.0E-10]
at org.testng.Assert.fail(Assert.java:99)
at org.testng.Assert.failNotEquals(Assert.java:1037)
at org.testng.Assert.assertEqualsImpl(Assert.java:140)
at org.testng.Assert.assertEquals(Assert.java:122)
at org.testng.Assert.assertEquals(Assert.java:629)
at org.testng.Assert.assertEquals(Assert.java:639)
at Acacemy.multiplicationTests.MultiplyOneAndZero(multiplicationTests.java:75)
at sun.reflect.NativeMethodAccessorImpl.invoke0(Native Method)
at sun.reflect.NativeMethodAccessorImpl.invoke(NativeMethodAccessorImpl.java:62)
at sun.reflect.DelegatingMethodAccessorImpl.invoke(DelegatingMethodAccessorImpl.java:43)
at java.lang.reflect.Method.invoke(Method.java:498)
at org.testng.internal.MethodInvocationHelper.invokeMethod(MethodInvocationHelper.java:132)
at org.testng.internal.TestInvoker.invokeMethod(TestInvoker.java:599)
at org.testng.internal.TestInvoker.invokeTestMethod(TestInvoker.java:174)
at org.testng.internal.MethodRunner.runInSequence(MethodRunner.java:46)
at org.testng.internal.TestInvoker$MethodInvocationAgent.invoke(TestInvoker.java:822)
at org.testng.internal.TestInvoker.invokeTestMethods(TestInvoker.java:147)
at org.testng.internal.TestMethodWorker.invokeTestMethods(TestMethodWorker.java:146)
at org.testng.internal.TestMethodWorker.run(TestMethodWorker.java:128)
at java.util.ArrayList.forEach(ArrayList.java:1257)
at org.testng.TestRunner.privateRun(TestRunner.java:764)
at org.testng.TestRunner.run(TestRunner.java:585)
at org.testng.SuiteRunner.runTest(SuiteRunner.java:384)
at org.testng.SuiteRunner.access$000(SuiteRunner.java:28)
at org.testng.SuiteRunner$SuiteWorker.run(SuiteRunner.java:425)
at org.testng.internal.thread.ThreadUtil.lambda$execute$0(ThreadUtil.java:66)
at java.util.concurrent.FutureTask.run(FutureTask.java:266)
at java.util.concurrent.ThreadPoolExecutor.runWorker(ThreadPoolExecutor.java:1149)
at java.util.concurrent.ThreadPoolExecutor$Worker.run(ThreadPoolExecutor.java:624)
at java.lang.Thread.run(Thread.java:748)
]]>
            </full-stacktrace>
          </exception> <!-- java.lang.AssertionError -->
          <reporter-output>
          </reporter-output>
        </test-method> <!-- MultiplyOneAndZero -->
        <test-method status="FAIL" signature="MultiplyZeroAndOne()[pri:0, instance:Acacemy.multiplicationTests@7a765367]" name="MultiplyZeroAndOne" duration-ms="5337" started-at="2021-03-14T15:51:51 GMT" finished-at="2021-03-14T15:51:56 GMT">
          <exception class="java.lang.AssertionError">
            <message>
              <![CDATA[expected [0] but found [1.0E-10]]]>
            </message>
            <full-stacktrace>
              <![CDATA[java.lang.AssertionError: expected [0] but found [1.0E-10]
at org.testng.Assert.fail(Assert.java:99)
at org.testng.Assert.failNotEquals(Assert.java:1037)
at org.testng.Assert.assertEqualsImpl(Assert.java:140)
at org.testng.Assert.assertEquals(Assert.java:122)
at org.testng.Assert.assertEquals(Assert.java:629)
at org.testng.Assert.assertEquals(Assert.java:639)
at Acacemy.multiplicationTests.MultiplyZeroAndOne(multiplicationTests.java:65)
at sun.reflect.NativeMethodAccessorImpl.invoke0(Native Method)
at sun.reflect.NativeMethodAccessorImpl.invoke(NativeMethodAccessorImpl.java:62)
at sun.reflect.DelegatingMethodAccessorImpl.invoke(DelegatingMethodAccessorImpl.java:43)
at java.lang.reflect.Method.invoke(Method.java:498)
at org.testng.internal.MethodInvocationHelper.invokeMethod(MethodInvocationHelper.java:132)
at org.testng.internal.TestInvoker.invokeMethod(TestInvoker.java:599)
at org.testng.internal.TestInvoker.invokeTestMethod(TestInvoker.java:174)
at org.testng.internal.MethodRunner.runInSequence(MethodRunner.java:46)
at org.testng.internal.TestInvoker$MethodInvocationAgent.invoke(TestInvoker.java:822)
at org.testng.internal.TestInvoker.invokeTestMethods(TestInvoker.java:147)
at org.testng.internal.TestMethodWorker.invokeTestMethods(TestMethodWorker.java:146)
at org.testng.internal.TestMethodWorker.run(TestMethodWorker.java:128)
at java.util.ArrayList.forEach(ArrayList.java:1257)
at org.testng.TestRunner.privateRun(TestRunner.java:764)
at org.testng.TestRunner.run(TestRunner.java:585)
at org.testng.SuiteRunner.runTest(SuiteRunner.java:384)
at org.testng.SuiteRunner.access$000(SuiteRunner.java:28)
at org.testng.SuiteRunner$SuiteWorker.run(SuiteRunner.java:425)
at org.testng.internal.thread.ThreadUtil.lambda$execute$0(ThreadUtil.java:66)
at java.util.concurrent.FutureTask.run(FutureTask.java:266)
at java.util.concurrent.ThreadPoolExecutor.runWorker(ThreadPoolExecutor.java:1149)
at java.util.concurrent.ThreadPoolExecutor$Worker.run(ThreadPoolExecutor.java:624)
at java.lang.Thread.run(Thread.java:748)
]]>
            </full-stacktrace>
          </exception> <!-- java.lang.AssertionError -->
          <reporter-output>
          </reporter-output>
        </test-method> <!-- MultiplyZeroAndOne -->
        <test-method status="FAIL" signature="MultiplyZeroAndZero()[pri:0, instance:Acacemy.multiplicationTests@7a765367]" name="MultiplyZeroAndZero" duration-ms="5238" started-at="2021-03-14T15:51:57 GMT" finished-at="2021-03-14T15:52:02 GMT">
          <exception class="java.lang.AssertionError">
            <message>
              <![CDATA[expected [0] but found [1.0E-10]]]>
            </message>
            <full-stacktrace>
              <![CDATA[java.lang.AssertionError: expected [0] but found [1.0E-10]
at org.testng.Assert.fail(Assert.java:99)
at org.testng.Assert.failNotEquals(Assert.java:1037)
at org.testng.Assert.assertEqualsImpl(Assert.java:140)
at org.testng.Assert.assertEquals(Assert.java:122)
at org.testng.Assert.assertEquals(Assert.java:629)
at org.testng.Assert.assertEquals(Assert.java:639)
at Acacemy.multiplicationTests.MultiplyZeroAndZero(multiplicationTests.java:54)
at sun.reflect.NativeMethodAccessorImpl.invoke0(Native Method)
at sun.reflect.NativeMethodAccessorImpl.invoke(NativeMethodAccessorImpl.java:62)
at sun.reflect.DelegatingMethodAccessorImpl.invoke(DelegatingMethodAccessorImpl.java:43)
at java.lang.reflect.Method.invoke(Method.java:498)
at org.testng.internal.MethodInvocationHelper.invokeMethod(MethodInvocationHelper.java:132)
at org.testng.internal.TestInvoker.invokeMethod(TestInvoker.java:599)
at org.testng.internal.TestInvoker.invokeTestMethod(TestInvoker.java:174)
at org.testng.internal.MethodRunner.runInSequence(MethodRunner.java:46)
at org.testng.internal.TestInvoker$MethodInvocationAgent.invoke(TestInvoker.java:822)
at org.testng.internal.TestInvoker.invokeTestMethods(TestInvoker.java:147)
at org.testng.internal.TestMethodWorker.invokeTestMethods(TestMethodWorker.java:146)
at org.testng.internal.TestMethodWorker.run(TestMethodWorker.java:128)
at java.util.ArrayList.forEach(ArrayList.java:1257)
at org.testng.TestRunner.privateRun(TestRunner.java:764)
at org.testng.TestRunner.run(TestRunner.java:585)
at org.testng.SuiteRunner.runTest(SuiteRunner.java:384)
at org.testng.SuiteRunner.access$000(SuiteRunner.java:28)
at org.testng.SuiteRunner$SuiteWorker.run(SuiteRunner.java:425)
at org.testng.internal.thread.ThreadUtil.lambda$execute$0(ThreadUtil.java:66)
at java.util.concurrent.FutureTask.run(FutureTask.java:266)
at java.util.concurrent.ThreadPoolExecutor.runWorker(ThreadPoolExecutor.java:1149)
at java.util.concurrent.ThreadPoolExecutor$Worker.run(ThreadPoolExecutor.java:624)
at java.lang.Thread.run(Thread.java:748)
]]>
            </full-stacktrace>
          </exception> <!-- java.lang.AssertionError -->
          <reporter-output>
          </reporter-output>
        </test-method> <!-- MultiplyZeroAndZero -->
        <test-method status="FAIL" signature="MultiplytwoNumbersBig()[pri:0, instance:Acacemy.multiplicationTests@7a765367]" name="MultiplytwoNumbersBig" duration-ms="5655" started-at="2021-03-14T15:52:02 GMT" finished-at="2021-03-14T15:52:08 GMT">
          <exception class="java.lang.AssertionError">
            <message>
              <![CDATA[expected [2.764000751148E12] but found [2.7463800107551217E18]]]>
            </message>
            <full-stacktrace>
              <![CDATA[java.lang.AssertionError: expected [2.764000751148E12] but found [2.7463800107551217E18]
at org.testng.Assert.fail(Assert.java:99)
at org.testng.Assert.failNotEquals(Assert.java:1037)
at org.testng.Assert.assertEqualsImpl(Assert.java:140)
at org.testng.Assert.assertEquals(Assert.java:122)
at org.testng.Assert.assertEquals(Assert.java:629)
at org.testng.Assert.assertEquals(Assert.java:639)
at Acacemy.multiplicationTests.MultiplytwoNumbersBig(multiplicationTests.java:34)
at sun.reflect.NativeMethodAccessorImpl.invoke0(Native Method)
at sun.reflect.NativeMethodAccessorImpl.invoke(NativeMethodAccessorImpl.java:62)
at sun.reflect.DelegatingMethodAccessorImpl.invoke(DelegatingMethodAccessorImpl.java:43)
at java.lang.reflect.Method.invoke(Method.java:498)
at org.testng.internal.MethodInvocationHelper.invokeMethod(MethodInvocationHelper.java:132)
at org.testng.internal.TestInvoker.invokeMethod(TestInvoker.java:599)
at org.testng.internal.TestInvoker.invokeTestMethod(TestInvoker.java:174)
at org.testng.internal.MethodRunner.runInSequence(MethodRunner.java:46)
at org.testng.internal.TestInvoker$MethodInvocationAgent.invoke(TestInvoker.java:822)
at org.testng.internal.TestInvoker.invokeTestMethods(TestInvoker.java:147)
at org.testng.internal.TestMethodWorker.invokeTestMethods(TestMethodWorker.java:146)
at org.testng.internal.TestMethodWorker.run(TestMethodWorker.java:128)
at java.util.ArrayList.forEach(ArrayList.java:1257)
at org.testng.TestRunner.privateRun(TestRunner.java:764)
at org.testng.TestRunner.run(TestRunner.java:585)
at org.testng.SuiteRunner.runTest(SuiteRunner.java:384)
at org.testng.SuiteRunner.access$000(SuiteRunner.java:28)
at org.testng.SuiteRunner$SuiteWorker.run(SuiteRunner.java:425)
at org.testng.internal.thread.ThreadUtil.lambda$execute$0(ThreadUtil.java:66)
at java.util.concurrent.FutureTask.run(FutureTask.java:266)
at java.util.concurrent.ThreadPoolExecutor.runWorker(ThreadPoolExecutor.java:1149)
at java.util.concurrent.ThreadPoolExecutor$Worker.run(ThreadPoolExecutor.java:624)
at java.lang.Thread.run(Thread.java:748)
]]>
            </full-stacktrace>
          </exception> <!-- java.lang.AssertionError -->
          <reporter-output>
          </reporter-output>
        </test-method> <!-- MultiplytwoNumbersBig -->
        <test-method status="PASS" signature="Teardown()[pri:0, instance:Acacemy.multiplicationTests@7a765367]" name="Teardown" is-config="true" duration-ms="77" started-at="2021-03-14T15:52:08 GMT" finished-at="2021-03-14T15:52:08 GMT">
          <reporter-output>
          </reporter-output>
        </test-method> <!-- Teardown -->
      </class> <!-- Acacemy.multiplicationTests -->
    </test> <!-- Multiplication -->
    <test name="Addition" duration-ms="66807" started-at="2021-03-14T15:51:07 GMT" finished-at="2021-03-14T15:52:13 GMT">
      <class name="Acacemy.additionTest">
        <test-method status="PASS" signature="initialization()[pri:0, instance:Acacemy.additionTest@6895a785]" name="initialization" is-config="true" duration-ms="7611" started-at="2021-03-14T15:51:07 GMT" finished-at="2021-03-14T15:51:14 GMT">
          <reporter-output>
          </reporter-output>
        </test-method> <!-- initialization -->
        <test-method status="FAIL" signature="AddAscendRangeAndDescendRange()[pri:0, instance:Acacemy.additionTest@6895a785]" name="AddAscendRangeAndDescendRange" duration-ms="6960" started-at="2021-03-14T15:51:14 GMT" finished-at="2021-03-14T15:51:21 GMT">
          <exception class="java.lang.AssertionError">
            <message>
              <![CDATA[expected [80235.0] but found [95117.5000000001]]]>
            </message>
            <full-stacktrace>
              <![CDATA[java.lang.AssertionError: expected [80235.0] but found [95117.5000000001]
at org.testng.Assert.fail(Assert.java:99)
at org.testng.Assert.failNotEquals(Assert.java:1037)
at org.testng.Assert.assertEqualsImpl(Assert.java:140)
at org.testng.Assert.assertEquals(Assert.java:122)
at org.testng.Assert.assertEquals(Assert.java:629)
at org.testng.Assert.assertEquals(Assert.java:639)
at Acacemy.additionTest.AddAscendRangeAndDescendRange(additionTest.java:29)
at sun.reflect.NativeMethodAccessorImpl.invoke0(Native Method)
at sun.reflect.NativeMethodAccessorImpl.invoke(NativeMethodAccessorImpl.java:62)
at sun.reflect.DelegatingMethodAccessorImpl.invoke(DelegatingMethodAccessorImpl.java:43)
at java.lang.reflect.Method.invoke(Method.java:498)
at org.testng.internal.MethodInvocationHelper.invokeMethod(MethodInvocationHelper.java:132)
at org.testng.internal.TestInvoker.invokeMethod(TestInvoker.java:599)
at org.testng.internal.TestInvoker.invokeTestMethod(TestInvoker.java:174)
at org.testng.internal.MethodRunner.runInSequence(MethodRunner.java:46)
at org.testng.internal.TestInvoker$MethodInvocationAgent.invoke(TestInvoker.java:822)
at org.testng.internal.TestInvoker.invokeTestMethods(TestInvoker.java:147)
at org.testng.internal.TestMethodWorker.invokeTestMethods(TestMethodWorker.java:146)
at org.testng.internal.TestMethodWorker.run(TestMethodWorker.java:128)
at java.util.ArrayList.forEach(ArrayList.java:1257)
at org.testng.TestRunner.privateRun(TestRunner.java:764)
at org.testng.TestRunner.run(TestRunner.java:585)
at org.testng.SuiteRunner.runTest(SuiteRunner.java:384)
at org.testng.SuiteRunner.access$000(SuiteRunner.java:28)
at org.testng.SuiteRunner$SuiteWorker.run(SuiteRunner.java:425)
at org.testng.internal.thread.ThreadUtil.lambda$execute$0(ThreadUtil.java:66)
at java.util.concurrent.FutureTask.run(FutureTask.java:266)
at java.util.concurrent.ThreadPoolExecutor.runWorker(ThreadPoolExecutor.java:1149)
at java.util.concurrent.ThreadPoolExecutor$Worker.run(ThreadPoolExecutor.java:624)
at java.lang.Thread.run(Thread.java:748)
]]>
            </full-stacktrace>
          </exception> <!-- java.lang.AssertionError -->
          <reporter-output>
          </reporter-output>
        </test-method> <!-- AddAscendRangeAndDescendRange -->
        <test-method status="FAIL" signature="AddBigNumberandOne()[pri:0, instance:Acacemy.additionTest@6895a785]" name="AddBigNumberandOne" duration-ms="5096" started-at="2021-03-14T15:51:22 GMT" finished-at="2021-03-14T15:51:27 GMT">
          <exception class="java.lang.AssertionError">
            <message>
              <![CDATA[expected [8989899.0] but found [95117.5000000002]]]>
            </message>
            <full-stacktrace>
              <![CDATA[java.lang.AssertionError: expected [8989899.0] but found [95117.5000000002]
at org.testng.Assert.fail(Assert.java:99)
at org.testng.Assert.failNotEquals(Assert.java:1037)
at org.testng.Assert.assertEqualsImpl(Assert.java:140)
at org.testng.Assert.assertEquals(Assert.java:122)
at org.testng.Assert.assertEquals(Assert.java:629)
at org.testng.Assert.assertEquals(Assert.java:639)
at Acacemy.additionTest.AddBigNumberandOne(additionTest.java:46)
at sun.reflect.NativeMethodAccessorImpl.invoke0(Native Method)
at sun.reflect.NativeMethodAccessorImpl.invoke(NativeMethodAccessorImpl.java:62)
at sun.reflect.DelegatingMethodAccessorImpl.invoke(DelegatingMethodAccessorImpl.java:43)
at java.lang.reflect.Method.invoke(Method.java:498)
at org.testng.internal.MethodInvocationHelper.invokeMethod(MethodInvocationHelper.java:132)
at org.testng.internal.TestInvoker.invokeMethod(TestInvoker.java:599)
at org.testng.internal.TestInvoker.invokeTestMethod(TestInvoker.java:174)
at org.testng.internal.MethodRunner.runInSequence(MethodRunner.java:46)
at org.testng.internal.TestInvoker$MethodInvocationAgent.invoke(TestInvoker.java:822)
at org.testng.internal.TestInvoker.invokeTestMethods(TestInvoker.java:147)
at org.testng.internal.TestMethodWorker.invokeTestMethods(TestMethodWorker.java:146)
at org.testng.internal.TestMethodWorker.run(TestMethodWorker.java:128)
at java.util.ArrayList.forEach(ArrayList.java:1257)
at org.testng.TestRunner.privateRun(TestRunner.java:764)
at org.testng.TestRunner.run(TestRunner.java:585)
at org.testng.SuiteRunner.runTest(SuiteRunner.java:384)
at org.testng.SuiteRunner.access$000(SuiteRunner.java:28)
at org.testng.SuiteRunner$SuiteWorker.run(SuiteRunner.java:425)
at org.testng.internal.thread.ThreadUtil.lambda$execute$0(ThreadUtil.java:66)
at java.util.concurrent.FutureTask.run(FutureTask.java:266)
at java.util.concurrent.ThreadPoolExecutor.runWorker(ThreadPoolExecutor.java:1149)
at java.util.concurrent.ThreadPoolExecutor$Worker.run(ThreadPoolExecutor.java:624)
at java.lang.Thread.run(Thread.java:748)
]]>
            </full-stacktrace>
          </exception> <!-- java.lang.AssertionError -->
          <reporter-output>
          </reporter-output>
        </test-method> <!-- AddBigNumberandOne -->
        <test-method status="FAIL" signature="AddDecimalNumbers()[pri:0, instance:Acacemy.additionTest@6895a785]" name="AddDecimalNumbers" duration-ms="5499" started-at="2021-03-14T15:51:27 GMT" finished-at="2021-03-14T15:51:32 GMT">
          <exception class="java.lang.AssertionError">
            <message>
              <![CDATA[expected [5.34] but found [25.351000000099997]]]>
            </message>
            <full-stacktrace>
              <![CDATA[java.lang.AssertionError: expected [5.34] but found [25.351000000099997]
at org.testng.Assert.fail(Assert.java:99)
at org.testng.Assert.failNotEquals(Assert.java:1037)
at org.testng.Assert.assertEqualsImpl(Assert.java:140)
at org.testng.Assert.assertEquals(Assert.java:122)
at org.testng.Assert.assertEquals(Assert.java:629)
at org.testng.Assert.assertEquals(Assert.java:639)
at Acacemy.additionTest.AddDecimalNumbers(additionTest.java:104)
at sun.reflect.NativeMethodAccessorImpl.invoke0(Native Method)
at sun.reflect.NativeMethodAccessorImpl.invoke(NativeMethodAccessorImpl.java:62)
at sun.reflect.DelegatingMethodAccessorImpl.invoke(DelegatingMethodAccessorImpl.java:43)
at java.lang.reflect.Method.invoke(Method.java:498)
at org.testng.internal.MethodInvocationHelper.invokeMethod(MethodInvocationHelper.java:132)
at org.testng.internal.TestInvoker.invokeMethod(TestInvoker.java:599)
at org.testng.internal.TestInvoker.invokeTestMethod(TestInvoker.java:174)
at org.testng.internal.MethodRunner.runInSequence(MethodRunner.java:46)
at org.testng.internal.TestInvoker$MethodInvocationAgent.invoke(TestInvoker.java:822)
at org.testng.internal.TestInvoker.invokeTestMethods(TestInvoker.java:147)
at org.testng.internal.TestMethodWorker.invokeTestMethods(TestMethodWorker.java:146)
at org.testng.internal.TestMethodWorker.run(TestMethodWorker.java:128)
at java.util.ArrayList.forEach(ArrayList.java:1257)
at org.testng.TestRunner.privateRun(TestRunner.java:764)
at org.testng.TestRunner.run(TestRunner.java:585)
at org.testng.SuiteRunner.runTest(SuiteRunner.java:384)
at org.testng.SuiteRunner.access$000(SuiteRunner.java:28)
at org.testng.SuiteRunner$SuiteWorker.run(SuiteRunner.java:425)
at org.testng.internal.thread.ThreadUtil.lambda$execute$0(ThreadUtil.java:66)
at java.util.concurrent.FutureTask.run(FutureTask.java:266)
at java.util.concurrent.ThreadPoolExecutor.runWorker(ThreadPoolExecutor.java:1149)
at java.util.concurrent.ThreadPoolExecutor$Worker.run(ThreadPoolExecutor.java:624)
at java.lang.Thread.run(Thread.java:748)
]]>
            </full-stacktrace>
          </exception> <!-- java.lang.AssertionError -->
          <reporter-output>
          </reporter-output>
        </test-method> <!-- AddDecimalNumbers -->
        <test-method status="FAIL" signature="AddMorethanTwoNumbers()[pri:0, instance:Acacemy.additionTest@6895a785]" name="AddMorethanTwoNumbers" duration-ms="5371" started-at="2021-03-14T15:51:33 GMT" finished-at="2021-03-14T15:51:38 GMT">
          <exception class="java.lang.AssertionError">
            <message>
              <![CDATA[expected [21.0] but found [131.0000000001]]]>
            </message>
            <full-stacktrace>
              <![CDATA[java.lang.AssertionError: expected [21.0] but found [131.0000000001]
at org.testng.Assert.fail(Assert.java:99)
at org.testng.Assert.failNotEquals(Assert.java:1037)
at org.testng.Assert.assertEqualsImpl(Assert.java:140)
at org.testng.Assert.assertEquals(Assert.java:122)
at org.testng.Assert.assertEquals(Assert.java:629)
at org.testng.Assert.assertEquals(Assert.java:639)
at Acacemy.additionTest.AddMorethanTwoNumbers(additionTest.java:83)
at sun.reflect.NativeMethodAccessorImpl.invoke0(Native Method)
at sun.reflect.NativeMethodAccessorImpl.invoke(NativeMethodAccessorImpl.java:62)
at sun.reflect.DelegatingMethodAccessorImpl.invoke(DelegatingMethodAccessorImpl.java:43)
at java.lang.reflect.Method.invoke(Method.java:498)
at org.testng.internal.MethodInvocationHelper.invokeMethod(MethodInvocationHelper.java:132)
at org.testng.internal.TestInvoker.invokeMethod(TestInvoker.java:599)
at org.testng.internal.TestInvoker.invokeTestMethod(TestInvoker.java:174)
at org.testng.internal.MethodRunner.runInSequence(MethodRunner.java:46)
at org.testng.internal.TestInvoker$MethodInvocationAgent.invoke(TestInvoker.java:822)
at org.testng.internal.TestInvoker.invokeTestMethods(TestInvoker.java:147)
at org.testng.internal.TestMethodWorker.invokeTestMethods(TestMethodWorker.java:146)
at org.testng.internal.TestMethodWorker.run(TestMethodWorker.java:128)
at java.util.ArrayList.forEach(ArrayList.java:1257)
at org.testng.TestRunner.privateRun(TestRunner.java:764)
at org.testng.TestRunner.run(TestRunner.java:585)
at org.testng.SuiteRunner.runTest(SuiteRunner.java:384)
at org.testng.SuiteRunner.access$000(SuiteRunner.java:28)
at org.testng.SuiteRunner$SuiteWorker.run(SuiteRunner.java:425)
at org.testng.internal.thread.ThreadUtil.lambda$execute$0(ThreadUtil.java:66)
at java.util.concurrent.FutureTask.run(FutureTask.java:266)
at java.util.concurrent.ThreadPoolExecutor.runWorker(ThreadPoolExecutor.java:1149)
at java.util.concurrent.ThreadPoolExecutor$Worker.run(ThreadPoolExecutor.java:624)
at java.lang.Thread.run(Thread.java:748)
]]>
            </full-stacktrace>
          </exception> <!-- java.lang.AssertionError -->
          <reporter-output>
          </reporter-output>
        </test-method> <!-- AddMorethanTwoNumbers -->
        <test-method status="FAIL" signature="AddNegativeandPositiveNumbers()[pri:0, instance:Acacemy.additionTest@6895a785]" name="AddNegativeandPositiveNumbers" duration-ms="5258" started-at="2021-03-14T15:51:38 GMT" finished-at="2021-03-14T15:51:44 GMT">
          <exception class="java.lang.AssertionError">
            <message>
              <![CDATA[expected [-7.0] but found [31.0000000001]]]>
            </message>
            <full-stacktrace>
              <![CDATA[java.lang.AssertionError: expected [-7.0] but found [31.0000000001]
at org.testng.Assert.fail(Assert.java:99)
at org.testng.Assert.failNotEquals(Assert.java:1037)
at org.testng.Assert.assertEqualsImpl(Assert.java:140)
at org.testng.Assert.assertEquals(Assert.java:122)
at org.testng.Assert.assertEquals(Assert.java:629)
at org.testng.Assert.assertEquals(Assert.java:639)
at Acacemy.additionTest.AddNegativeandPositiveNumbers(additionTest.java:97)
at sun.reflect.NativeMethodAccessorImpl.invoke0(Native Method)
at sun.reflect.NativeMethodAccessorImpl.invoke(NativeMethodAccessorImpl.java:62)
at sun.reflect.DelegatingMethodAccessorImpl.invoke(DelegatingMethodAccessorImpl.java:43)
at java.lang.reflect.Method.invoke(Method.java:498)
at org.testng.internal.MethodInvocationHelper.invokeMethod(MethodInvocationHelper.java:132)
at org.testng.internal.TestInvoker.invokeMethod(TestInvoker.java:599)
at org.testng.internal.TestInvoker.invokeTestMethod(TestInvoker.java:174)
at org.testng.internal.MethodRunner.runInSequence(MethodRunner.java:46)
at org.testng.internal.TestInvoker$MethodInvocationAgent.invoke(TestInvoker.java:822)
at org.testng.internal.TestInvoker.invokeTestMethods(TestInvoker.java:147)
at org.testng.internal.TestMethodWorker.invokeTestMethods(TestMethodWorker.java:146)
at org.testng.internal.TestMethodWorker.run(TestMethodWorker.java:128)
at java.util.ArrayList.forEach(ArrayList.java:1257)
at org.testng.TestRunner.privateRun(TestRunner.java:764)
at org.testng.TestRunner.run(TestRunner.java:585)
at org.testng.SuiteRunner.runTest(SuiteRunner.java:384)
at org.testng.SuiteRunner.access$000(SuiteRunner.java:28)
at org.testng.SuiteRunner$SuiteWorker.run(SuiteRunner.java:425)
at org.testng.internal.thread.ThreadUtil.lambda$execute$0(ThreadUtil.java:66)
at java.util.concurrent.FutureTask.run(FutureTask.java:266)
at java.util.concurrent.ThreadPoolExecutor.runWorker(ThreadPoolExecutor.java:1149)
at java.util.concurrent.ThreadPoolExecutor$Worker.run(ThreadPoolExecutor.java:624)
at java.lang.Thread.run(Thread.java:748)
]]>
            </full-stacktrace>
          </exception> <!-- java.lang.AssertionError -->
          <reporter-output>
          </reporter-output>
        </test-method> <!-- AddNegativeandPositiveNumbers -->
        <test-method status="FAIL" signature="AddNmmbersgivesSevenDigitResult()[pri:0, instance:Acacemy.additionTest@6895a785]" name="AddNmmbersgivesSevenDigitResult" duration-ms="5733" started-at="2021-03-14T15:51:44 GMT" finished-at="2021-03-14T15:51:50 GMT">
          <exception class="java.lang.AssertionError">
            <message>
              <![CDATA[expected [5555555.0] but found [1.27727727725E10]]]>
            </message>
            <full-stacktrace>
              <![CDATA[java.lang.AssertionError: expected [5555555.0] but found [1.27727727725E10]
at org.testng.Assert.fail(Assert.java:99)
at org.testng.Assert.failNotEquals(Assert.java:1037)
at org.testng.Assert.assertEqualsImpl(Assert.java:140)
at org.testng.Assert.assertEquals(Assert.java:122)
at org.testng.Assert.assertEquals(Assert.java:629)
at org.testng.Assert.assertEquals(Assert.java:639)
at Acacemy.additionTest.AddNmmbersgivesSevenDigitResult(additionTest.java:39)
at sun.reflect.NativeMethodAccessorImpl.invoke0(Native Method)
at sun.reflect.NativeMethodAccessorImpl.invoke(NativeMethodAccessorImpl.java:62)
at sun.reflect.DelegatingMethodAccessorImpl.invoke(DelegatingMethodAccessorImpl.java:43)
at java.lang.reflect.Method.invoke(Method.java:498)
at org.testng.internal.MethodInvocationHelper.invokeMethod(MethodInvocationHelper.java:132)
at org.testng.internal.TestInvoker.invokeMethod(TestInvoker.java:599)
at org.testng.internal.TestInvoker.invokeTestMethod(TestInvoker.java:174)
at org.testng.internal.MethodRunner.runInSequence(MethodRunner.java:46)
at org.testng.internal.TestInvoker$MethodInvocationAgent.invoke(TestInvoker.java:822)
at org.testng.internal.TestInvoker.invokeTestMethods(TestInvoker.java:147)
at org.testng.internal.TestMethodWorker.invokeTestMethods(TestMethodWorker.java:146)
at org.testng.internal.TestMethodWorker.run(TestMethodWorker.java:128)
at java.util.ArrayList.forEach(ArrayList.java:1257)
at org.testng.TestRunner.privateRun(TestRunner.java:764)
at org.testng.TestRunner.run(TestRunner.java:585)
at org.testng.SuiteRunner.runTest(SuiteRunner.java:384)
at org.testng.SuiteRunner.access$000(SuiteRunner.java:28)
at org.testng.SuiteRunner$SuiteWorker.run(SuiteRunner.java:425)
at org.testng.internal.thread.ThreadUtil.lambda$execute$0(ThreadUtil.java:66)
at java.util.concurrent.FutureTask.run(FutureTask.java:266)
at java.util.concurrent.ThreadPoolExecutor.runWorker(ThreadPoolExecutor.java:1149)
at java.util.concurrent.ThreadPoolExecutor$Worker.run(ThreadPoolExecutor.java:624)
at java.lang.Thread.run(Thread.java:748)
]]>
            </full-stacktrace>
          </exception> <!-- java.lang.AssertionError -->
          <reporter-output>
          </reporter-output>
        </test-method> <!-- AddNmmbersgivesSevenDigitResult -->
        <test-method status="FAIL" signature="AddTwoBigNumbers()[pri:0, instance:Acacemy.additionTest@6895a785]" name="AddTwoBigNumbers" duration-ms="6209" started-at="2021-03-14T15:51:50 GMT" finished-at="2021-03-14T15:51:56 GMT">
          <exception class="java.lang.AssertionError">
            <message>
              <![CDATA[expected [9.34934934E8] but found [6.23168592534E11]]]>
            </message>
            <full-stacktrace>
              <![CDATA[java.lang.AssertionError: expected [9.34934934E8] but found [6.23168592534E11]
at org.testng.Assert.fail(Assert.java:99)
at org.testng.Assert.failNotEquals(Assert.java:1037)
at org.testng.Assert.assertEqualsImpl(Assert.java:140)
at org.testng.Assert.assertEquals(Assert.java:122)
at org.testng.Assert.assertEquals(Assert.java:629)
at org.testng.Assert.assertEquals(Assert.java:639)
at Acacemy.additionTest.AddTwoBigNumbers(additionTest.java:52)
at sun.reflect.NativeMethodAccessorImpl.invoke0(Native Method)
at sun.reflect.NativeMethodAccessorImpl.invoke(NativeMethodAccessorImpl.java:62)
at sun.reflect.DelegatingMethodAccessorImpl.invoke(DelegatingMethodAccessorImpl.java:43)
at java.lang.reflect.Method.invoke(Method.java:498)
at org.testng.internal.MethodInvocationHelper.invokeMethod(MethodInvocationHelper.java:132)
at org.testng.internal.TestInvoker.invokeMethod(TestInvoker.java:599)
at org.testng.internal.TestInvoker.invokeTestMethod(TestInvoker.java:174)
at org.testng.internal.MethodRunner.runInSequence(MethodRunner.java:46)
at org.testng.internal.TestInvoker$MethodInvocationAgent.invoke(TestInvoker.java:822)
at org.testng.internal.TestInvoker.invokeTestMethods(TestInvoker.java:147)
at org.testng.internal.TestMethodWorker.invokeTestMethods(TestMethodWorker.java:146)
at org.testng.internal.TestMethodWorker.run(TestMethodWorker.java:128)
at java.util.ArrayList.forEach(ArrayList.java:1257)
at org.testng.TestRunner.privateRun(TestRunner.java:764)
at org.testng.TestRunner.run(TestRunner.java:585)
at org.testng.SuiteRunner.runTest(SuiteRunner.java:384)
at org.testng.SuiteRunner.access$000(SuiteRunner.java:28)
at org.testng.SuiteRunner$SuiteWorker.run(SuiteRunner.java:425)
at org.testng.internal.thread.ThreadUtil.lambda$execute$0(ThreadUtil.java:66)
at java.util.concurrent.FutureTask.run(FutureTask.java:266)
at java.util.concurrent.ThreadPoolExecutor.runWorker(ThreadPoolExecutor.java:1149)
at java.util.concurrent.ThreadPoolExecutor$Worker.run(ThreadPoolExecutor.java:624)
at java.lang.Thread.run(Thread.java:748)
]]>
            </full-stacktrace>
          </exception> <!-- java.lang.AssertionError -->
          <reporter-output>
          </reporter-output>
        </test-method> <!-- AddTwoBigNumbers -->
        <test-method status="FAIL" signature="AddTwoSingleDigits()[pri:0, instance:Acacemy.additionTest@6895a785]" name="AddTwoSingleDigits" duration-ms="5247" started-at="2021-03-14T15:51:57 GMT" finished-at="2021-03-14T15:52:02 GMT">
          <exception class="java.lang.AssertionError">
            <message>
              <![CDATA[expected [8.0] but found [8.0000000001]]]>
            </message>
            <full-stacktrace>
              <![CDATA[java.lang.AssertionError: expected [8.0] but found [8.0000000001]
at org.testng.Assert.fail(Assert.java:99)
at org.testng.Assert.failNotEquals(Assert.java:1037)
at org.testng.Assert.assertEqualsImpl(Assert.java:140)
at org.testng.Assert.assertEquals(Assert.java:122)
at org.testng.Assert.assertEquals(Assert.java:629)
at org.testng.Assert.assertEquals(Assert.java:639)
at Acacemy.additionTest.AddTwoSingleDigits(additionTest.java:90)
at sun.reflect.NativeMethodAccessorImpl.invoke0(Native Method)
at sun.reflect.NativeMethodAccessorImpl.invoke(NativeMethodAccessorImpl.java:62)
at sun.reflect.DelegatingMethodAccessorImpl.invoke(DelegatingMethodAccessorImpl.java:43)
at java.lang.reflect.Method.invoke(Method.java:498)
at org.testng.internal.MethodInvocationHelper.invokeMethod(MethodInvocationHelper.java:132)
at org.testng.internal.TestInvoker.invokeMethod(TestInvoker.java:599)
at org.testng.internal.TestInvoker.invokeTestMethod(TestInvoker.java:174)
at org.testng.internal.MethodRunner.runInSequence(MethodRunner.java:46)
at org.testng.internal.TestInvoker$MethodInvocationAgent.invoke(TestInvoker.java:822)
at org.testng.internal.TestInvoker.invokeTestMethods(TestInvoker.java:147)
at org.testng.internal.TestMethodWorker.invokeTestMethods(TestMethodWorker.java:146)
at org.testng.internal.TestMethodWorker.run(TestMethodWorker.java:128)
at java.util.ArrayList.forEach(ArrayList.java:1257)
at org.testng.TestRunner.privateRun(TestRunner.java:764)
at org.testng.TestRunner.run(TestRunner.java:585)
at org.testng.SuiteRunner.runTest(SuiteRunner.java:384)
at org.testng.SuiteRunner.access$000(SuiteRunner.java:28)
at org.testng.SuiteRunner$SuiteWorker.run(SuiteRunner.java:425)
at org.testng.internal.thread.ThreadUtil.lambda$execute$0(ThreadUtil.java:66)
at java.util.concurrent.FutureTask.run(FutureTask.java:266)
at java.util.concurrent.ThreadPoolExecutor.runWorker(ThreadPoolExecutor.java:1149)
at java.util.concurrent.ThreadPoolExecutor$Worker.run(ThreadPoolExecutor.java:624)
at java.lang.Thread.run(Thread.java:748)
]]>
            </full-stacktrace>
          </exception> <!-- java.lang.AssertionError -->
          <reporter-output>
          </reporter-output>
        </test-method> <!-- AddTwoSingleDigits -->
        <test-method status="FAIL" signature="AddZeroAndOne()[pri:0, instance:Acacemy.additionTest@6895a785]" name="AddZeroAndOne" duration-ms="5202" started-at="2021-03-14T15:52:02 GMT" finished-at="2021-03-14T15:52:07 GMT">
          <exception class="java.lang.AssertionError">
            <message>
              <![CDATA[expected [1.0] but found [1.0000000001]]]>
            </message>
            <full-stacktrace>
              <![CDATA[java.lang.AssertionError: expected [1.0] but found [1.0000000001]
at org.testng.Assert.fail(Assert.java:99)
at org.testng.Assert.failNotEquals(Assert.java:1037)
at org.testng.Assert.assertEqualsImpl(Assert.java:140)
at org.testng.Assert.assertEquals(Assert.java:122)
at org.testng.Assert.assertEquals(Assert.java:629)
at org.testng.Assert.assertEquals(Assert.java:639)
at Acacemy.additionTest.AddZeroAndOne(additionTest.java:72)
at sun.reflect.NativeMethodAccessorImpl.invoke0(Native Method)
at sun.reflect.NativeMethodAccessorImpl.invoke(NativeMethodAccessorImpl.java:62)
at sun.reflect.DelegatingMethodAccessorImpl.invoke(DelegatingMethodAccessorImpl.java:43)
at java.lang.reflect.Method.invoke(Method.java:498)
at org.testng.internal.MethodInvocationHelper.invokeMethod(MethodInvocationHelper.java:132)
at org.testng.internal.TestInvoker.invokeMethod(TestInvoker.java:599)
at org.testng.internal.TestInvoker.invokeTestMethod(TestInvoker.java:174)
at org.testng.internal.MethodRunner.runInSequence(MethodRunner.java:46)
at org.testng.internal.TestInvoker$MethodInvocationAgent.invoke(TestInvoker.java:822)
at org.testng.internal.TestInvoker.invokeTestMethods(TestInvoker.java:147)
at org.testng.internal.TestMethodWorker.invokeTestMethods(TestMethodWorker.java:146)
at org.testng.internal.TestMethodWorker.run(TestMethodWorker.java:128)
at java.util.ArrayList.forEach(ArrayList.java:1257)
at org.testng.TestRunner.privateRun(TestRunner.java:764)
at org.testng.TestRunner.run(TestRunner.java:585)
at org.testng.SuiteRunner.runTest(SuiteRunner.java:384)
at org.testng.SuiteRunner.access$000(SuiteRunner.java:28)
at org.testng.SuiteRunner$SuiteWorker.run(SuiteRunner.java:425)
at org.testng.internal.thread.ThreadUtil.lambda$execute$0(ThreadUtil.java:66)
at java.util.concurrent.FutureTask.run(FutureTask.java:266)
at java.util.concurrent.ThreadPoolExecutor.runWorker(ThreadPoolExecutor.java:1149)
at java.util.concurrent.ThreadPoolExecutor$Worker.run(ThreadPoolExecutor.java:624)
at java.lang.Thread.run(Thread.java:748)
]]>
            </full-stacktrace>
          </exception> <!-- java.lang.AssertionError -->
          <reporter-output>
          </reporter-output>
        </test-method> <!-- AddZeroAndOne -->
        <test-method status="FAIL" signature="AddZeroAndZero()[pri:0, instance:Acacemy.additionTest@6895a785]" name="AddZeroAndZero" duration-ms="5177" started-at="2021-03-14T15:52:08 GMT" finished-at="2021-03-14T15:52:13 GMT">
          <exception class="java.lang.AssertionError">
            <message>
              <![CDATA[expected [0] but found [1.0E-10]]]>
            </message>
            <full-stacktrace>
              <![CDATA[java.lang.AssertionError: expected [0] but found [1.0E-10]
at org.testng.Assert.fail(Assert.java:99)
at org.testng.Assert.failNotEquals(Assert.java:1037)
at org.testng.Assert.assertEqualsImpl(Assert.java:140)
at org.testng.Assert.assertEquals(Assert.java:122)
at org.testng.Assert.assertEquals(Assert.java:629)
at org.testng.Assert.assertEquals(Assert.java:639)
at Acacemy.additionTest.AddZeroAndZero(additionTest.java:60)
at sun.reflect.NativeMethodAccessorImpl.invoke0(Native Method)
at sun.reflect.NativeMethodAccessorImpl.invoke(NativeMethodAccessorImpl.java:62)
at sun.reflect.DelegatingMethodAccessorImpl.invoke(DelegatingMethodAccessorImpl.java:43)
at java.lang.reflect.Method.invoke(Method.java:498)
at org.testng.internal.MethodInvocationHelper.invokeMethod(MethodInvocationHelper.java:132)
at org.testng.internal.TestInvoker.invokeMethod(TestInvoker.java:599)
at org.testng.internal.TestInvoker.invokeTestMethod(TestInvoker.java:174)
at org.testng.internal.MethodRunner.runInSequence(MethodRunner.java:46)
at org.testng.internal.TestInvoker$MethodInvocationAgent.invoke(TestInvoker.java:822)
at org.testng.internal.TestInvoker.invokeTestMethods(TestInvoker.java:147)
at org.testng.internal.TestMethodWorker.invokeTestMethods(TestMethodWorker.java:146)
at org.testng.internal.TestMethodWorker.run(TestMethodWorker.java:128)
at java.util.ArrayList.forEach(ArrayList.java:1257)
at org.testng.TestRunner.privateRun(TestRunner.java:764)
at org.testng.TestRunner.run(TestRunner.java:585)
at org.testng.SuiteRunner.runTest(SuiteRunner.java:384)
at org.testng.SuiteRunner.access$000(SuiteRunner.java:28)
at org.testng.SuiteRunner$SuiteWorker.run(SuiteRunner.java:425)
at org.testng.internal.thread.ThreadUtil.lambda$execute$0(ThreadUtil.java:66)
at java.util.concurrent.FutureTask.run(FutureTask.java:266)
at java.util.concurrent.ThreadPoolExecutor.runWorker(ThreadPoolExecutor.java:1149)
at java.util.concurrent.ThreadPoolExecutor$Worker.run(ThreadPoolExecutor.java:624)
at java.lang.Thread.run(Thread.java:748)
]]>
            </full-stacktrace>
          </exception> <!-- java.lang.AssertionError -->
          <reporter-output>
          </reporter-output>
        </test-method> <!-- AddZeroAndZero -->
        <test-method status="PASS" signature="Teardown()[pri:0, instance:Acacemy.additionTest@6895a785]" name="Teardown" is-config="true" duration-ms="119" started-at="2021-03-14T15:52:13 GMT" finished-at="2021-03-14T15:52:13 GMT">
          <reporter-output>
          </reporter-output>
        </test-method> <!-- Teardown -->
      </class> <!-- Acacemy.additionTest -->
    </test> <!-- Addition -->
    <test name="Verifying Elements" duration-ms="80910" started-at="2021-03-14T15:51:07 GMT" finished-at="2021-03-14T15:52:27 GMT">
      <class name="Acacemy.VerifyingElementsareClickable">
        <test-method status="PASS" signature="initialization()[pri:0, instance:Acacemy.VerifyingElementsareClickable@3dfc5fb8]" name="initialization" is-config="true" duration-ms="7964" started-at="2021-03-14T15:51:07 GMT" finished-at="2021-03-14T15:51:14 GMT">
          <reporter-output>
          </reporter-output>
        </test-method> <!-- initialization -->
        <test-method status="PASS" signature="clear()[pri:0, instance:Acacemy.VerifyingElementsareClickable@3dfc5fb8]" name="clear" duration-ms="171" started-at="2021-03-14T15:51:14 GMT" finished-at="2021-03-14T15:51:15 GMT">
          <reporter-output>
          </reporter-output>
        </test-method> <!-- clear -->
        <test-method status="PASS" signature="divide()[pri:0, instance:Acacemy.VerifyingElementsareClickable@3dfc5fb8]" name="divide" duration-ms="5289" started-at="2021-03-14T15:51:15 GMT" finished-at="2021-03-14T15:51:20 GMT">
          <reporter-output>
          </reporter-output>
        </test-method> <!-- divide -->
        <test-method status="PASS" signature="minus()[pri:0, instance:Acacemy.VerifyingElementsareClickable@3dfc5fb8]" name="minus" duration-ms="5149" started-at="2021-03-14T15:51:20 GMT" finished-at="2021-03-14T15:51:25 GMT">
          <reporter-output>
          </reporter-output>
        </test-method> <!-- minus -->
        <test-method status="PASS" signature="multiply()[pri:0, instance:Acacemy.VerifyingElementsareClickable@3dfc5fb8]" name="multiply" duration-ms="5138" started-at="2021-03-14T15:51:25 GMT" finished-at="2021-03-14T15:51:30 GMT">
          <reporter-output>
          </reporter-output>
        </test-method> <!-- multiply -->
        <test-method status="PASS" signature="number0()[pri:0, instance:Acacemy.VerifyingElementsareClickable@3dfc5fb8]" name="number0" duration-ms="5138" started-at="2021-03-14T15:51:30 GMT" finished-at="2021-03-14T15:51:35 GMT">
          <reporter-output>
          </reporter-output>
        </test-method> <!-- number0 -->
        <test-method status="PASS" signature="number1()[pri:0, instance:Acacemy.VerifyingElementsareClickable@3dfc5fb8]" name="number1" duration-ms="5135" started-at="2021-03-14T15:51:35 GMT" finished-at="2021-03-14T15:51:41 GMT">
          <reporter-output>
          </reporter-output>
        </test-method> <!-- number1 -->
        <test-method status="PASS" signature="number2()[pri:0, instance:Acacemy.VerifyingElementsareClickable@3dfc5fb8]" name="number2" duration-ms="5134" started-at="2021-03-14T15:51:41 GMT" finished-at="2021-03-14T15:51:46 GMT">
          <reporter-output>
          </reporter-output>
        </test-method> <!-- number2 -->
        <test-method status="PASS" signature="number3()[pri:0, instance:Acacemy.VerifyingElementsareClickable@3dfc5fb8]" name="number3" duration-ms="5168" started-at="2021-03-14T15:51:46 GMT" finished-at="2021-03-14T15:51:51 GMT">
          <reporter-output>
          </reporter-output>
        </test-method> <!-- number3 -->
        <test-method status="PASS" signature="number4()[pri:0, instance:Acacemy.VerifyingElementsareClickable@3dfc5fb8]" name="number4" duration-ms="5185" started-at="2021-03-14T15:51:51 GMT" finished-at="2021-03-14T15:51:56 GMT">
          <reporter-output>
          </reporter-output>
        </test-method> <!-- number4 -->
        <test-method status="PASS" signature="number5()[pri:0, instance:Acacemy.VerifyingElementsareClickable@3dfc5fb8]" name="number5" duration-ms="5188" started-at="2021-03-14T15:51:56 GMT" finished-at="2021-03-14T15:52:01 GMT">
          <reporter-output>
          </reporter-output>
        </test-method> <!-- number5 -->
        <test-method status="PASS" signature="number6()[pri:0, instance:Acacemy.VerifyingElementsareClickable@3dfc5fb8]" name="number6" duration-ms="5118" started-at="2021-03-14T15:52:01 GMT" finished-at="2021-03-14T15:52:06 GMT">
          <reporter-output>
          </reporter-output>
        </test-method> <!-- number6 -->
        <test-method status="FAIL" signature="number7()[pri:0, instance:Acacemy.VerifyingElementsareClickable@3dfc5fb8]" name="number7" duration-ms="5170" started-at="2021-03-14T15:52:06 GMT" finished-at="2021-03-14T15:52:12 GMT">
          <exception class="java.lang.AssertionError">
            <message>
              <![CDATA[PASSED expected [7] but found [77]]]>
            </message>
            <full-stacktrace>
              <![CDATA[java.lang.AssertionError: PASSED expected [7] but found [77]
at org.testng.Assert.fail(Assert.java:99)
at org.testng.Assert.failNotEquals(Assert.java:1037)
at org.testng.Assert.assertEqualsImpl(Assert.java:140)
at org.testng.Assert.assertEquals(Assert.java:122)
at org.testng.Assert.assertEquals(Assert.java:629)
at Acacemy.VerifyingElementsareClickable.number7(VerifyingElementsareClickable.java:133)
at sun.reflect.NativeMethodAccessorImpl.invoke0(Native Method)
at sun.reflect.NativeMethodAccessorImpl.invoke(NativeMethodAccessorImpl.java:62)
at sun.reflect.DelegatingMethodAccessorImpl.invoke(DelegatingMethodAccessorImpl.java:43)
at java.lang.reflect.Method.invoke(Method.java:498)
at org.testng.internal.MethodInvocationHelper.invokeMethod(MethodInvocationHelper.java:132)
at org.testng.internal.TestInvoker.invokeMethod(TestInvoker.java:599)
at org.testng.internal.TestInvoker.invokeTestMethod(TestInvoker.java:174)
at org.testng.internal.MethodRunner.runInSequence(MethodRunner.java:46)
at org.testng.internal.TestInvoker$MethodInvocationAgent.invoke(TestInvoker.java:822)
at org.testng.internal.TestInvoker.invokeTestMethods(TestInvoker.java:147)
at org.testng.internal.TestMethodWorker.invokeTestMethods(TestMethodWorker.java:146)
at org.testng.internal.TestMethodWorker.run(TestMethodWorker.java:128)
at java.util.ArrayList.forEach(ArrayList.java:1257)
at org.testng.TestRunner.privateRun(TestRunner.java:764)
at org.testng.TestRunner.run(TestRunner.java:585)
at org.testng.SuiteRunner.runTest(SuiteRunner.java:384)
at org.testng.SuiteRunner.access$000(SuiteRunner.java:28)
at org.testng.SuiteRunner$SuiteWorker.run(SuiteRunner.java:425)
at org.testng.internal.thread.ThreadUtil.lambda$execute$0(ThreadUtil.java:66)
at java.util.concurrent.FutureTask.run(FutureTask.java:266)
at java.util.concurrent.ThreadPoolExecutor.runWorker(ThreadPoolExecutor.java:1149)
at java.util.concurrent.ThreadPoolExecutor$Worker.run(ThreadPoolExecutor.java:624)
at java.lang.Thread.run(Thread.java:748)
]]>
            </full-stacktrace>
          </exception> <!-- java.lang.AssertionError -->
          <reporter-output>
          </reporter-output>
        </test-method> <!-- number7 -->
        <test-method status="PASS" signature="number8()[pri:0, instance:Acacemy.VerifyingElementsareClickable@3dfc5fb8]" name="number8" duration-ms="5139" started-at="2021-03-14T15:52:12 GMT" finished-at="2021-03-14T15:52:17 GMT">
          <reporter-output>
          </reporter-output>
        </test-method> <!-- number8 -->
        <test-method status="PASS" signature="number9()[pri:0, instance:Acacemy.VerifyingElementsareClickable@3dfc5fb8]" name="number9" duration-ms="5138" started-at="2021-03-14T15:52:17 GMT" finished-at="2021-03-14T15:52:22 GMT">
          <reporter-output>
          </reporter-output>
        </test-method> <!-- number9 -->
        <test-method status="PASS" signature="plus()[pri:0, instance:Acacemy.VerifyingElementsareClickable@3dfc5fb8]" name="plus" duration-ms="5212" started-at="2021-03-14T15:52:22 GMT" finished-at="2021-03-14T15:52:27 GMT">
          <reporter-output>
          </reporter-output>
        </test-method> <!-- plus -->
        <test-method status="PASS" signature="Teardown()[pri:0, instance:Acacemy.VerifyingElementsareClickable@3dfc5fb8]" name="Teardown" is-config="true" duration-ms="91" started-at="2021-03-14T15:52:27 GMT" finished-at="2021-03-14T15:52:27 GMT">
          <reporter-output>
          </reporter-output>
        </test-method> <!-- Teardown -->
      </class> <!-- Acacemy.VerifyingElementsareClickable -->
    </test> <!-- Verifying Elements -->
  </suite> <!-- Suite -->
</testng-results>
